Workbook

Sheet 目次
A1: 目次 | B1: シート
A2: 月データ | B2: =HYPERLINK("#"&A2&"!A1",A2) -> 月データ
A3: 1 | B3: =HYPERLINK("#"&A3&"!A1",A3) -> 1
A4: 2 | B4: =HYPERLINK("#"&A4&"!A1",A4) -> 2
A5: 3 | B5: =HYPERLINK("#"&A5&"!A1",A5) -> 3
A6: 4 | B6: =HYPERLINK("#"&A6&"!A1",A6) -> 4
A7: 5 | B7: =HYPERLINK("#"&A7&"!A1",A7) -> 5
A8: 6 | B8: =HYPERLINK("#"&A8&"!A1",A8) -> 6
A9: 7 | B9: =HYPERLINK("#"&A9&"!A1",A9) -> 7
A10: 8 | B10: =HYPERLINK("#"&A10&"!A1",A10) -> 8
A11: 9 | B11: =HYPERLINK("#"&A11&"!A1",A11) -> 9
A12: 10 | B12: =HYPERLINK("#"&A12&"!A1",A12) -> 10
A13: 11 | B13: =HYPERLINK("#"&A13&"!A1",A13) -> 11
A14: 12 | B14: =HYPERLINK("#"&A14&"!A1",A14) -> 12
... A33: 31 | B33: =HYPERLINK("#"&A33&"!A1",A33) -> 31

Sheet 月データ
A1: 日付 | B1: 曜日 | C1: 窓口売上 | D1: 保険売上 | E1: 総売 | F1: 総人 | G1: 保人 | H1: 初 | I1: 2以上 | J1: MT | K1: P・深 | L1: B | M1: I | N1: 産後 | O1: 延長 | P1: 15下 | Q1: 高校 | R1: 大学 | S1: 20代 | T1: 30代 | U1: 40代 | V1: 50代 | W1: 60代 | X1: 70代 | Y1: 80代 | Z1: 90代 | AA1: 男 | AB1: 女 | AC1: 15・20 | AD1: 30 | AE1: 4～90 | AF1: 午前 | AG1: 午後 | AH1: 夕以降 | AJ1: 目次 | AK1: シート
A2: =DATE(A36,B36,1) -> 45839 | B2: =TEXT(A2,"aaa") -> 火 | C2: ='1'!R51 -> 0 | E2: =SUM(C2,D2) -> 0 | F2: ='1'!R43 -> 0 | G2: ='1'!R44 -> 0 | H2: ='1'!Y5 -> 0 | I2: =SUM('1'!Y7,'1'!Y9,'1'!Y11,'1'!Y13,'1'!Y15,'1'!Y17,'1'!Y19) -> 0 | J2: ='1'!W7 -> 0 | K2: ='1'!W9 -> 0 | L2: ='1'!W11 -> 0 | M2: ='1'!W13 -> 0 | N2: ='1'!W15 -> 0 | O2: ='1'!W17 -> 0 | P2: ='1'!Z5 -> 0 | Q2: ='1'!Z7 -> 0 | R2: ='1'!Z9 -> 0 | S2: ='1'!Z11 -> 0 | T2: ='1'!Z13 -> 0 | U2: ='1'!Z15 -> 0 | V2: ='1'!Z17 -> 0 | W2: ='1'!Z19 -> 0 | X2: ='1'!Z21 -> 0 | Y2: ='1'!Z23 -> 0 | Z2: ='1'!Z25 -> 0 | AA2: ='1'!AA5 -> 0 | AB2: ='1'!AA7 -> 0 | AC2: =SUM('1'!X5,'1'!X7) -> 0 | AD2: ='1'!X9 -> 0 | AE2: =SUM('1'!X11,'1'!X13,'1'!X15,'1'!X17,'1'!X19,'1'!X21) -> 0 | AF2: ='1'!AB4 -> 0 | AG2: ='1'!AB6 -> 0 | AH2: ='1'!AB8 -> 0 | AJ2: 月データ | AK2: =HYPERLINK("#"&AJ2&"!A1",AJ2) -> 月データ
A3: =A2+1 -> 45840 | B3: =TEXT(A3,"aaa") -> 水 | C3: ='2'!R51 -> 0 | E3: =SUM(C3,D3) -> 0 | F3: ='2'!R43 -> 0 | G3: ='2'!R44 -> 0 | H3: ='2'!Y5 -> 0 | I3: =SUM('2'!Y7,'2'!Y9,'2'!Y11,'2'!Y13,'2'!Y15,'2'!Y17,'2'!Y19) -> 0 | J3: ='2'!W7 -> 0 | K3: ='2'!W9 -> 0 | L3: ='2'!W11 -> 0 | M3: ='2'!W13 -> 0 | N3: ='2'!W15 -> 0 | O3: ='2'!W17 -> 0 | P3: ='2'!Z5 -> 0 | Q3: ='2'!Z7 -> 0 | R3: ='2'!Z9 -> 0 | S3: ='2'!Z11 -> 0 | T3: ='2'!Z13 -> 0 | U3: ='2'!Z15 -> 0 | V3: ='2'!Z17 -> 0 | W3: ='2'!Z19 -> 0 | X3: ='2'!Z21 -> 0 | Y3: ='2'!Z23 -> 0 | Z3: ='2'!Z25 -> 0 | AA3: ='2'!AA5 -> 0 | AB3: ='2'!AA7 -> 0 | AC3: =SUM('2'!X5,'2'!X7) -> 0 | AD3: ='2'!X9 -> 0 | AE3: =SUM('2'!X11,'2'!X13,'2'!X15,'2'!X17,'2'!X19,'2'!X21) -> 0 | AF3: ='2'!AB4 -> 0 | AG3: ='2'!AB6 -> 0 | AH3: ='2'!AB8 -> 0 | AJ3: 1 | AK3: =HYPERLINK("#"&AJ3&"!A1",AJ3) -> 1
A4: =A3+1 -> 45841 | B4: =TEXT(A4,"aaa") -> 木 | C4: ='3'!R51 -> 0 | E4: =SUM(C4,D4) -> 0 | F4: ='3'!R43 -> 0 | G4: ='3'!R44 -> 0 | H4: ='3'!Y5 -> 0 | I4: =SUM('3'!Y7,'3'!Y9,'3'!Y11,'3'!Y13,'3'!Y15,'3'!Y17,'3'!Y19) -> 0 | J4: ='3'!W7 -> 0 | K4: ='3'!W9 -> 0 | L4: ='3'!W11 -> 0 | M4: ='3'!W13 -> 0 | N4: ='3'!W15 -> 0 | O4: ='3'!W17 -> 0 | P4: ='3'!Z5 -> 0 | Q4: ='3'!Z7 -> 0 | R4: ='3'!Z9 -> 0 | S4: ='3'!Z11 -> 0 | T4: ='3'!Z13 -> 0 | U4: ='3'!Z15 -> 0 | V4: ='3'!Z17 -> 0 | W4: ='3'!Z19 -> 0 | X4: ='3'!Z21 -> 0 | Y4: ='3'!Z23 -> 0 | Z4: ='3'!Z25 -> 0 | AA4: ='3'!AA5 -> 0 | AB4: ='3'!AA7 -> 0 | AC4: =SUM('3'!X5,'3'!X7) -> 0 | AD4: ='3'!X9 -> 0 | AE4: =SUM('3'!X11,'3'!X13,'3'!X15,'3'!X17,'3'!X19,'3'!X21) -> 0 | AF4: ='3'!AB4 -> 0 | AG4: ='3'!AB6 -> 0 | AH4: ='3'!AB8 -> 0 | AJ4: 2 | AK4: =HYPERLINK("#"&AJ4&"!A1",AJ4) -> 2
A5: =A4+1 -> 45842 | B5: =TEXT(A5,"aaa") -> 金 | C5: ='4'!R51 -> 0 | E5: =SUM(C5,D5) -> 0 | F5: ='4'!R43 -> 0 | G5: ='4'!R44 -> 0 | H5: ='4'!Y5 -> 0 | I5: =SUM('4'!Y7,'4'!Y9,'4'!Y11,'4'!Y13,'4'!Y15,'4'!Y17,'4'!Y19) -> 0 | J5: ='4'!W7 -> 0 | K5: ='4'!W9 -> 0 | L5: ='4'!W11 -> 0 | M5: ='4'!W13 -> 0 | N5: ='4'!W15 -> 0 | O5: ='4'!W17 -> 0 | P5: ='4'!Z5 -> 0 | Q5: ='4'!Z7 -> 0 | R5: ='4'!Z9 -> 0 | S5: ='4'!Z11 -> 0 | T5: ='4'!Z13 -> 0 | U5: ='4'!Z15 -> 0 | V5: ='4'!Z17 -> 0 | W5: ='4'!Z19 -> 0 | X5: ='4'!Z21 -> 0 | Y5: ='4'!Z23 -> 0 | Z5: ='4'!Z25 -> 0 | AA5: ='4'!AA5 -> 0 | AB5: ='4'!AA7 -> 0 | AC5: =SUM('4'!X5,'4'!X7) -> 0 | AD5: ='4'!X9 -> 0 | AE5: =SUM('4'!X11,'4'!X13,'4'!X15,'4'!X17,'4'!X19,'4'!X21) -> 0 | AF5: ='4'!AB4 -> 0 | AG5: ='4'!AB6 -> 0 | AH5: ='4'!AB8 -> 0 | AJ5: 3 | AK5: =HYPERLINK("#"&AJ5&"!A1",AJ5) -> 3
A6: =A5+1 -> 45843 | B6: =TEXT(A6,"aaa") -> 土 | C6: ='5'!R51 -> 0 | E6: =SUM(C6,D6) -> 0 | F6: ='5'!R43 -> 0 | G6: ='5'!R44 -> 0 | H6: ='5'!Y5 -> 0 | I6: =SUM('5'!Y7,'5'!Y9,'5'!Y11,'5'!Y13,'5'!Y15,'5'!Y17,'5'!Y19) -> 0 | J6: ='5'!W7 -> 0 | K6: ='5'!W9 -> 0 | L6: ='5'!W11 -> 0 | M6: ='5'!W13 -> 0 | N6: ='5'!W15 -> 0 | O6: ='5'!W17 -> 0 | P6: ='5'!Z5 -> 0 | Q6: ='5'!Z7 -> 0 | R6: ='5'!Z9 -> 0 | S6: ='5'!Z11 -> 0 | T6: ='5'!Z13 -> 0 | U6: ='5'!Z15 -> 0 | V6: ='5'!Z17 -> 0 | W6: ='5'!Z19 -> 0 | X6: ='5'!Z21 -> 0 | Y6: ='5'!Z23 -> 0 | Z6: ='5'!Z25 -> 0 | AA6: ='5'!AA5 -> 0 | AB6: ='5'!AA7 -> 0 | AC6: =SUM('5'!X5,'5'!X7) -> 0 | AD6: ='5'!X9 -> 0 | AE6: =SUM('5'!X11,'5'!X13,'5'!X15,'5'!X17,'5'!X19,'5'!X21) -> 0 | AF6: ='5'!AB4 -> 0 | AG6: ='5'!AB6 -> 0 | AH6: ='5'!AB8 -> 0 | AJ6: 4 | AK6: =HYPERLINK("#"&AJ6&"!A1",AJ6) -> 4
A7: =A6+1 -> 45844 | B7: =TEXT(A7,"aaa") -> 日 | C7: ='6'!R51 -> 0 | E7: =SUM(C7,D7) -> 0 | F7: ='6'!R43 -> 0 | G7: ='6'!R44 -> 0 | H7: ='6'!Y5 -> 0 | I7: =SUM('6'!Y7,'6'!Y9,'6'!Y11,'6'!Y13,'6'!Y15,'6'!Y17,'6'!Y19) -> 0 | J7: ='6'!W7 -> 0 | K7: ='6'!W9 -> 0 | L7: ='6'!W11 -> 0 | M7: ='6'!W13 -> 0 | N7: ='6'!W15 -> 0 | O7: ='6'!W17 -> 0 | P7: ='6'!Z5 -> 0 | Q7: ='6'!Z7 -> 0 | R7: ='6'!Z9 -> 0 | S7: ='6'!Z11 -> 0 | T7: ='6'!Z13 -> 0 | U7: ='6'!Z15 -> 0 | V7: ='6'!Z17 -> 0 | W7: ='6'!Z19 -> 0 | X7: ='6'!Z21 -> 0 | Y7: ='6'!Z23 -> 0 | Z7: ='6'!Z25 -> 0 | AA7: ='6'!AA5 -> 0 | AB7: ='6'!AA7 -> 0 | AC7: =SUM('6'!X5,'6'!X7) -> 0 | AD7: ='6'!X9 -> 0 | AE7: =SUM('6'!X11,'6'!X13,'6'!X15,'6'!X17,'6'!X19,'6'!X21) -> 0 | AF7: ='6'!AB4 -> 0 | AG7: ='6'!AB6 -> 0 | AH7: ='6'!AB8 -> 0 | AJ7: 5 | AK7: =HYPERLINK("#"&AJ7&"!A1",AJ7) -> 5
A8: =A7+1 -> 45845 | B8: =TEXT(A8,"aaa") -> 月 | C8: ='7'!R51 -> 0 | E8: =SUM(C8,D8) -> 0 | F8: ='7'!R43 -> 0 | G8: ='7'!R44 -> 0 | H8: ='7'!Y5 -> 0 | I8: =SUM('7'!Y7,'7'!Y9,'7'!Y11,'7'!Y13,'7'!Y15,'7'!Y17,'7'!Y19) -> 0 | J8: ='7'!W7 -> 0 | K8: ='7'!W9 -> 0 | L8: ='7'!W11 -> 0 | M8: ='7'!W13 -> 0 | N8: ='7'!W15 -> 0 | O8: ='7'!W17 -> 0 | P8: ='7'!Z5 -> 0 | Q8: ='7'!Z7 -> 0 | R8: ='7'!Z9 -> 0 | S8: ='7'!Z11 -> 0 | T8: ='7'!Z13 -> 0 | U8: ='7'!Z15 -> 0 | V8: ='7'!Z17 -> 0 | W8: ='7'!Z19 -> 0 | X8: ='7'!Z21 -> 0 | Y8: ='7'!Z23 -> 0 | Z8: ='7'!Z25 -> 0 | AA8: ='7'!AA5 -> 0 | AB8: ='7'!AA7 -> 0 | AC8: =SUM('7'!X5,'7'!X7) -> 0 | AD8: ='7'!X9 -> 0 | AE8: =SUM('7'!X11,'7'!X13,'7'!X15,'7'!X17,'7'!X19,'7'!X21) -> 0 | AF8: ='7'!AB4 -> 0 | AG8: ='7'!AB6 -> 0 | AH8: ='7'!AB8 -> 0 | AJ8: 6 | AK8: =HYPERLINK("#"&AJ8&"!A1",AJ8) -> 6
A9: =A8+1 -> 45846 | B9: =TEXT(A9,"aaa") -> 火 | C9: ='8'!R51 -> 0 | E9: =SUM(C9,D9) -> 0 | F9: ='8'!R43 -> 0 | G9: ='8'!R44 -> 0 | H9: ='8'!Y5 -> 0 | I9: =SUM('8'!Y7,'8'!Y9,'8'!Y11,'8'!Y13,'8'!Y15,'8'!Y17,'8'!Y19) -> 0 | J9: ='8'!W7 -> 0 | K9: ='8'!W9 -> 0 | L9: ='8'!W11 -> 0 | M9: ='8'!W13 -> 0 | N9: ='8'!W15 -> 0 | O9: ='8'!W17 -> 0 | P9: ='8'!Z5 -> 0 | Q9: ='8'!Z7 -> 0 | R9: ='8'!Z9 -> 0 | S9: ='8'!Z11 -> 0 | T9: ='8'!Z13 -> 0 | U9: ='8'!Z15 -> 0 | V9: ='8'!Z17 -> 0 | W9: ='8'!Z19 -> 0 | X9: ='8'!Z21 -> 0 | Y9: ='8'!Z23 -> 0 | Z9: ='8'!Z25 -> 0 | AA9: ='8'!AA5 -> 0 | AB9: ='8'!AA7 -> 0 | AC9: =SUM('8'!X5,'8'!X7) -> 0 | AD9: ='8'!X9 -> 0 | AE9: =SUM('8'!X11,'8'!X13,'8'!X15,'8'!X17,'8'!X19,'8'!X21) -> 0 | AF9: ='8'!AB4 -> 0 | AG9: ='8'!AB6 -> 0 | AH9: ='8'!AB8 -> 0 | AJ9: 7 | AK9: =HYPERLINK("#"&AJ9&"!A1",AJ9) -> 7
A10: =A9+1 -> 45847 | B10: =TEXT(A10,"aaa") -> 水 | C10: ='9'!R51 -> 0 | E10: =SUM(C10,D10) -> 0 | F10: ='9'!R43 -> 0 | G10: ='9'!R44 -> 0 | H10: ='9'!Y5 -> 0 | I10: =SUM('9'!Y7,'9'!Y9,'9'!Y11,'9'!Y13,'9'!Y15,'9'!Y17,'9'!Y19) -> 0 | J10: ='9'!W7 -> 0 | K10: ='9'!W9 -> 0 | L10: ='9'!W11 -> 0 | M10: ='9'!W13 -> 0 | N10: ='9'!W15 -> 0 | O10: ='9'!W17 -> 0 | P10: ='9'!Z5 -> 0 | Q10: ='9'!Z7 -> 0 | R10: ='9'!Z9 -> 0 | S10: ='9'!Z11 -> 0 | T10: ='9'!Z13 -> 0 | U10: ='9'!Z15 -> 0 | V10: ='9'!Z17 -> 0 | W10: ='9'!Z19 -> 0 | X10: ='9'!Z21 -> 0 | Y10: ='9'!Z23 -> 0 | Z10: ='9'!Z25 -> 0 | AA10: ='9'!AA5 -> 0 | AB10: ='9'!AA7 -> 0 | AC10: =SUM('9'!X5,'9'!X7) -> 0 | AD10: ='9'!X9 -> 0 | AE10: =SUM('9'!X11,'9'!X13,'9'!X15,'9'!X17,'9'!X19,'9'!X21) -> 0 | AF10: ='9'!AB4 -> 0 | AG10: ='9'!AB6 -> 0 | AH10: ='9'!AB8 -> 0 | AJ10: 8 | AK10: =HYPERLINK("#"&AJ10&"!A1",AJ10) -> 8
A11: =A10+1 -> 45848 | B11: =TEXT(A11,"aaa") -> 木 | C11: ='10'!R51 -> 0 | E11: =SUM(C11,D11) -> 0 | F11: ='10'!R43 -> 0 | G11: ='10'!R44 -> 0 | H11: ='10'!Y5 -> 0 | I11: =SUM('10'!Y7,'10'!Y9,'10'!Y11,'10'!Y13,'10'!Y15,'10'!Y17,'10'!Y19) -> 0 | J11: ='10'!W7 -> 0 | K11: ='10'!W9 -> 0 | L11: ='10'!W11 -> 0 | M11: ='10'!W13 -> 0 | N11: ='10'!W15 -> 0 | O11: ='10'!W17 -> 0 | P11: ='10'!Z5 -> 0 | Q11: ='10'!Z7 -> 0 | R11: ='10'!Z9 -> 0 | S11: ='10'!Z11 -> 0 | T11: ='10'!Z13 -> 0 | U11: ='10'!Z15 -> 0 | V11: ='10'!Z17 -> 0 | W11: ='10'!Z19 -> 0 | X11: ='10'!Z21 -> 0 | Y11: ='10'!Z23 -> 0 | Z11: ='10'!Z25 -> 0 | AA11: ='10'!AA5 -> 0 | AB11: ='10'!AA7 -> 0 | AC11: =SUM('10'!X5,'10'!X7) -> 0 | AD11: ='10'!X9 -> 0 | AE11: =SUM('10'!X11,'10'!X13,'10'!X15,'10'!X17,'10'!X19,'10'!X21) -> 0 | AF11: ='10'!AB4 -> 0 | AG11: ='10'!AB6 -> 0 | AH11: ='10'!AB8 -> 0 | AJ11: 9 | AK11: =HYPERLINK("#"&AJ11&"!A1",AJ11) -> 9
A12: =A11+1 -> 45849 | B12: =TEXT(A12,"aaa") -> 金 | C12: ='11'!R51 -> 0 | E12: =SUM(C12,D12) -> 0 | F12: ='11'!R43 -> 0 | G12: ='11'!R44 -> 0 | H12: ='11'!Y5 -> 0 | I12: =SUM('11'!Y7,'11'!Y9,'11'!Y11,'11'!Y13,'11'!Y15,'11'!Y17,'11'!Y19) -> 0 | J12: ='11'!W7 -> 0 | K12: ='11'!W9 -> 0 | L12: ='11'!W11 -> 0 | M12: ='11'!W13 -> 0 | N12: ='11'!W15 -> 0 | O12: ='11'!W17 -> 0 | P12: ='11'!Z5 -> 0 | Q12: ='11'!Z7 -> 0 | R12: ='11'!Z9 -> 0 | S12: ='11'!Z11 -> 0 | T12: ='11'!Z13 -> 0 | U12: ='11'!Z15 -> 0 | V12: ='11'!Z17 -> 0 | W12: ='11'!Z19 -> 0 | X12: ='11'!Z21 -> 0 | Y12: ='11'!Z23 -> 0 | Z12: ='11'!Z25 -> 0 | AA12: ='11'!AA5 -> 0 | AB12: ='11'!AA7 -> 0 | AC12: =SUM('11'!X5,'11'!X7) -> 0 | AD12: ='11'!X9 -> 0 | AE12: =SUM('11'!X11,'11'!X13,'11'!X15,'11'!X17,'11'!X19,'11'!X21) -> 0 | AF12: ='11'!AB4 -> 0 | AG12: ='11'!AB6 -> 0 | AH12: ='11'!AB8 -> 0 | AJ12: 10 | AK12: =HYPERLINK("#"&AJ12&"!A1",AJ12) -> 10
A13: =A12+1 -> 45850 | B13: =TEXT(A13,"aaa") -> 土 | C13: ='12'!R51 -> 0 | E13: =SUM(C13,D13) -> 0 | F13: ='12'!R43 -> 0 | G13: ='12'!R44 -> 0 | H13: ='12'!Y5 -> 0 | I13: =SUM('12'!Y7,'12'!Y9,'12'!Y11,'12'!Y13,'12'!Y15,'12'!Y17,'12'!Y19) -> 0 | J13: ='12'!W7 -> 0 | K13: ='12'!W9 -> 0 | L13: ='12'!W11 -> 0 | M13: ='12'!W13 -> 0 | N13: ='12'!W15 -> 0 | O13: ='12'!W17 -> 0 | P13: ='12'!Z5 -> 0 | Q13: ='12'!Z7 -> 0 | R13: ='12'!Z9 -> 0 | S13: ='12'!Z11 -> 0 | T13: ='12'!Z13 -> 0 | U13: ='12'!Z15 -> 0 | V13: ='12'!Z17 -> 0 | W13: ='12'!Z19 -> 0 | X13: ='12'!Z21 -> 0 | Y13: ='12'!Z23 -> 0 | Z13: ='12'!Z25 -> 0 | AA13: ='12'!AA5 -> 0 | AB13: ='12'!AA7 -> 0 | AC13: =SUM('12'!X5,'12'!X7) -> 0 | AD13: ='12'!X9 -> 0 | AE13: =SUM('12'!X11,'12'!X13,'12'!X15,'12'!X17,'12'!X19,'12'!X21) -> 0 | AF13: ='12'!AB4 -> 0 | AG13: ='12'!AB6 -> 0 | AH13: ='12'!AB8 -> 0 | AJ13: 11 | AK13: =HYPERLINK("#"&AJ13&"!A1",AJ13) -> 11
A14: =A13+1 -> 45851 | B14: =TEXT(A14,"aaa") -> 日 | C14: ='13'!R51 -> 0 | E14: =SUM(C14,D14) -> 0 | F14: ='13'!R43 -> 0 | G14: ='13'!R44 -> 0 | H14: ='13'!Y5 -> 0 | I14: =SUM('13'!Y7,'13'!Y9,'13'!Y11,'13'!Y13,'13'!Y15,'13'!Y17,'13'!Y19) -> 0 | J14: ='13'!W7 -> 0 | K14: ='13'!W9 -> 0 | L14: ='13'!W11 -> 0 | M14: ='13'!W13 -> 0 | N14: ='13'!W15 -> 0 | O14: ='13'!W17 -> 0 | P14: ='13'!Z5 -> 0 | Q14: ='13'!Z7 -> 0 | R14: ='13'!Z9 -> 0 | S14: ='13'!Z11 -> 0 | T14: ='13'!Z13 -> 0 | U14: ='13'!Z15 -> 0 | V14: ='13'!Z17 -> 0 | W14: ='13'!Z19 -> 0 | X14: ='13'!Z21 -> 0 | Y14: ='13'!Z23 -> 0 | Z14: ='13'!Z25 -> 0 | AA14: ='13'!AA5 -> 0 | AB14: ='13'!AA7 -> 0 | AC14: =SUM('13'!X5,'13'!X7) -> 0 | AD14: ='13'!X9 -> 0 | AE14: =SUM('13'!X11,'13'!X13,'13'!X15,'13'!X17,'13'!X19,'13'!X21) -> 0 | AF14: ='13'!AB4 -> 0 | AG14: ='13'!AB6 -> 0 | AH14: ='13'!AB8 -> 0 | AJ14: 12 | AK14: =HYPERLINK("#"&AJ14&"!A1",AJ14) -> 12
A15: =A14+1 -> 45852 | B15: =TEXT(A15,"aaa") -> 月 | C15: ='14'!R51 -> 0 | E15: =SUM(C15,D15) -> 0 | F15: ='14'!R43 -> 0 | G15: ='14'!R44 -> 0 | H15: ='14'!Y5 -> 0 | I15: =SUM('14'!Y7,'14'!Y9,'14'!Y11,'14'!Y13,'14'!Y15,'14'!Y17,'14'!Y19) -> 0 | J15: ='14'!W7 -> 0 | K15: ='14'!W9 -> 0 | L15: ='14'!W11 -> 0 | M15: ='14'!W13 -> 0 | N15: ='14'!W15 -> 0 | O15: ='14'!W17 -> 0 | P15: ='14'!Z5 -> 0 | Q15: ='14'!Z7 -> 0 | R15: ='14'!Z9 -> 0 | S15: ='14'!Z11 -> 0 | T15: ='14'!Z13 -> 0 | U15: ='14'!Z15 -> 0 | V15: ='14'!Z17 -> 0 | W15: ='14'!Z19 -> 0 | X15: ='14'!Z21 -> 0 | Y15: ='14'!Z23 -> 0 | Z15: ='14'!Z25 -> 0 | AA15: ='14'!AA5 -> 0 | AB15: ='14'!AA7 -> 0 | AC15: =SUM('14'!X5,'14'!X7) -> 0 | AD15: ='14'!X9 -> 0 | AE15: =SUM('14'!X11,'14'!X13,'14'!X15,'14'!X17,'14'!X19,'14'!X21) -> 0 | AF15: ='14'!AB4 -> 0 | AG15: ='14'!AB6 -> 0 | AH15: ='14'!AB8 -> 0 | AJ15: 13 | AK15: =HYPERLINK("#"&AJ15&"!A1",AJ15) -> 13
A16: =A15+1 -> 45853 | B16: =TEXT(A16,"aaa") -> 火 | C16: ='15'!R51 -> 0 | E16: =SUM(C16,D16) -> 0 | F16: ='15'!R43 -> 0 | G16: ='15'!R44 -> 0 | H16: ='15'!Y5 -> 0 | I16: =SUM('15'!Y7,'15'!Y9,'15'!Y11,'15'!Y13,'15'!Y15,'15'!Y17,'15'!Y19) -> 0 | J16: ='15'!W7 -> 0 | K16: ='15'!W9 -> 0 | L16: ='15'!W11 -> 0 | M16: ='15'!W13 -> 0 | N16: ='15'!W15 -> 0 | O16: ='15'!W17 -> 0 | P16: ='15'!Z5 -> 0 | Q16: ='15'!Z7 -> 0 | R16: ='15'!Z9 -> 0 | S16: ='15'!Z11 -> 0 | T16: ='15'!Z13 -> 0 | U16: ='15'!Z15 -> 0 | V16: ='15'!Z17 -> 0 | W16: ='15'!Z19 -> 0 | X16: ='15'!Z21 -> 0 | Y16: ='15'!Z23 -> 0 | Z16: ='15'!Z25 -> 0 | AA16: ='15'!AA5 -> 0 | AB16: ='15'!AA7 -> 0 | AC16: =SUM('15'!X5,'15'!X7) -> 0 | AD16: ='15'!X9 -> 0 | AE16: =SUM('15'!X11,'15'!X13,'15'!X15,'15'!X17,'15'!X19,'15'!X21) -> 0 | AF16: ='15'!AB4 -> 0 | AG16: ='15'!AB6 -> 0 | AH16: ='15'!AB8 -> 0 | AJ16: 14 | AK16: =HYPERLINK("#"&AJ16&"!A1",AJ16) -> 14
A17: =A16+1 -> 45854 | B17: =TEXT(A17,"aaa") -> 水 | C17: ='16'!R51 -> 0 | E17: =SUM(C17,D17) -> 0 | F17: ='16'!R43 -> 0 | G17: ='16'!R44 -> 0 | H17: ='16'!Y5 -> 0 | I17: =SUM('16'!Y7,'16'!Y9,'16'!Y11,'16'!Y13,'16'!Y15,'16'!Y17,'16'!Y19) -> 0 | J17: ='16'!W7 -> 0 | K17: ='16'!W9 -> 0 | L17: ='16'!W11 -> 0 | M17: ='16'!W13 -> 0 | N17: ='16'!W15 -> 0 | O17: ='16'!W17 -> 0 | P17: ='16'!Z5 -> 0 | Q17: ='16'!Z7 -> 0 | R17: ='16'!Z9 -> 0 | S17: ='16'!Z11 -> 0 | T17: ='16'!Z13 -> 0 | U17: ='16'!Z15 -> 0 | V17: ='16'!Z17 -> 0 | W17: ='16'!Z19 -> 0 | X17: ='16'!Z21 -> 0 | Y17: ='16'!Z23 -> 0 | Z17: ='16'!Z25 -> 0 | AA17: ='16'!AA5 -> 0 | AB17: ='16'!AA7 -> 0 | AC17: =SUM('16'!X5,'16'!X7) -> 0 | AD17: ='16'!X9 -> 0 | AE17: =SUM('16'!X11,'16'!X13,'16'!X15,'16'!X17,'16'!X19,'16'!X21) -> 0 | AF17: ='16'!AB4 -> 0 | AG17: ='16'!AB6 -> 0 | AH17: ='16'!AB8 -> 0 | AJ17: 15 | AK17: =HYPERLINK("#"&AJ17&"!A1",AJ17) -> 15
A18: =A17+1 -> 45855 | B18: =TEXT(A18,"aaa") -> 木 | C18: ='17'!R51 -> 0 | E18: =SUM(C18,D18) -> 0 | F18: ='17'!R43 -> 0 | G18: ='17'!R44 -> 0 | H18: ='17'!Y5 -> 0 | I18: =SUM('17'!Y7,'17'!Y9,'17'!Y11,'17'!Y13,'17'!Y15,'17'!Y17,'17'!Y19) -> 0 | J18: ='17'!W7 -> 0 | K18: ='17'!W9 -> 0 | L18: ='17'!W11 -> 0 | M18: ='17'!W13 -> 0 | N18: ='17'!W15 -> 0 | O18: ='17'!W17 -> 0 | P18: ='17'!Z5 -> 0 | Q18: ='17'!Z7 -> 0 | R18: ='17'!Z9 -> 0 | S18: ='17'!Z11 -> 0 | T18: ='17'!Z13 -> 0 | U18: ='17'!Z15 -> 0 | V18: ='17'!Z17 -> 0 | W18: ='17'!Z19 -> 0 | X18: ='17'!Z21 -> 0 | Y18: ='17'!Z23 -> 0 | Z18: ='17'!Z25 -> 0 | AA18: ='17'!AA5 -> 0 | AB18: ='17'!AA7 -> 0 | AC18: =SUM('17'!X5,'17'!X7) -> 0 | AD18: ='17'!X9 -> 0 | AE18: =SUM('17'!X11,'17'!X13,'17'!X15,'17'!X17,'17'!X19,'17'!X21) -> 0 | AF18: ='17'!AB4 -> 0 | AG18: ='17'!AB6 -> 0 | AH18: ='17'!AB8 -> 0 | AJ18: 16 | AK18: =HYPERLINK("#"&AJ18&"!A1",AJ18) -> 16
A19: =A18+1 -> 45856 | B19: =TEXT(A19,"aaa") -> 金 | C19: ='18'!R51 -> 0 | E19: =SUM(C19,D19) -> 0 | F19: ='18'!R43 -> 0 | G19: ='18'!R44 -> 0 | H19: ='18'!Y5 -> 0 | I19: =SUM('18'!Y7,'18'!Y9,'18'!Y11,'18'!Y13,'18'!Y15,'18'!Y17,'18'!Y19) -> 0 | J19: ='18'!W7 -> 0 | K19: ='18'!W9 -> 0 | L19: ='18'!W11 -> 0 | M19: ='18'!W13 -> 0 | N19: ='18'!W15 -> 0 | O19: ='18'!W17 -> 0 | P19: ='18'!Z5 -> 0 | Q19: ='18'!Z7 -> 0 | R19: ='18'!Z9 -> 0 | S19: ='18'!Z11 -> 0 | T19: ='18'!Z13 -> 0 | U19: ='18'!Z15 -> 0 | V19: ='18'!Z17 -> 0 | W19: ='18'!Z19 -> 0 | X19: ='18'!Z21 -> 0 | Y19: ='18'!Z23 -> 0 | Z19: ='18'!Z25 -> 0 | AA19: ='18'!AA5 -> 0 | AB19: ='18'!AA7 -> 0 | AC19: =SUM('18'!X5,'18'!X7) -> 0 | AD19: ='18'!X9 -> 0 | AE19: =SUM('18'!X11,'18'!X13,'18'!X15,'18'!X17,'18'!X19,'18'!X21) -> 0 | AF19: ='18'!AB4 -> 0 | AG19: ='18'!AB6 -> 0 | AH19: ='18'!AB8 -> 0 | AJ19: 17 | AK19: =HYPERLINK("#"&AJ19&"!A1",AJ19) -> 17
A20: =A19+1 -> 45857 | B20: =TEXT(A20,"aaa") -> 土 | C20: ='19'!R51 -> 0 | E20: =SUM(C20,D20) -> 0 | F20: ='19'!R43 -> 0 | G20: ='19'!R44 -> 0 | H20: ='19'!Y5 -> 0 | I20: =SUM('19'!Y7,'19'!Y9,'19'!Y11,'19'!Y13,'19'!Y15,'19'!Y17,'19'!Y19) -> 0 | J20: ='19'!W7 -> 0 | K20: ='19'!W9 -> 0 | L20: ='19'!W11 -> 0 | M20: ='19'!W13 -> 0 | N20: ='19'!W15 -> 0 | O20: ='19'!W17 -> 0 | P20: ='19'!Z5 -> 0 | Q20: ='19'!Z7 -> 0 | R20: ='19'!Z9 -> 0 | S20: ='19'!Z11 -> 0 | T20: ='19'!Z13 -> 0 | U20: ='19'!Z15 -> 0 | V20: ='19'!Z17 -> 0 | W20: ='19'!Z19 -> 0 | X20: ='19'!Z21 -> 0 | Y20: ='19'!Z23 -> 0 | Z20: ='19'!Z25 -> 0 | AA20: ='19'!AA5 -> 0 | AB20: ='19'!AA7 -> 0 | AC20: =SUM('19'!X5,'19'!X7) -> 0 | AD20: ='19'!X9 -> 0 | AE20: =SUM('19'!X11,'19'!X13,'19'!X15,'19'!X17,'19'!X19,'19'!X21) -> 0 | AF20: ='19'!AB4 -> 0 | AG20: ='19'!AB6 -> 0 | AH20: ='19'!AB8 -> 0 | AJ20: 18 | AK20: =HYPERLINK("#"&AJ20&"!A1",AJ20) -> 18
A21: =A20+1 -> 45858 | B21: =TEXT(A21,"aaa") -> 日 | C21: ='20'!R51 -> 0 | E21: =SUM(C21,D21) -> 0 | F21: ='20'!R43 -> 0 | G21: ='20'!R44 -> 0 | H21: ='20'!Y5 -> 0 | I21: =SUM('20'!Y7,'20'!Y9,'20'!Y11,'20'!Y13,'20'!Y15,'20'!Y17,'20'!Y19) -> 0 | J21: ='20'!W7 -> 0 | K21: ='20'!W9 -> 0 | L21: ='20'!W11 -> 0 | M21: ='20'!W13 -> 0 | N21: ='20'!W15 -> 0 | O21: ='20'!W17 -> 0 | P21: ='20'!Z5 -> 0 | Q21: ='20'!Z7 -> 0 | R21: ='20'!Z9 -> 0 | S21: ='20'!Z11 -> 0 | T21: ='20'!Z13 -> 0 | U21: ='20'!Z15 -> 0 | V21: ='20'!Z17 -> 0 | W21: ='20'!Z19 -> 0 | X21: ='20'!Z21 -> 0 | Y21: ='20'!Z23 -> 0 | Z21: ='20'!Z25 -> 0 | AA21: ='20'!AA5 -> 0 | AB21: ='20'!AA7 -> 0 | AC21: =SUM('20'!X5,'20'!X7) -> 0 | AD21: ='20'!X9 -> 0 | AE21: =SUM('20'!X11,'20'!X13,'20'!X15,'20'!X17,'20'!X19,'20'!X21) -> 0 | AF21: ='20'!AB4 -> 0 | AG21: ='20'!AB6 -> 0 | AH21: ='20'!AB8 -> 0 | AJ21: 19 | AK21: =HYPERLINK("#"&AJ21&"!A1",AJ21) -> 19
A22: =A21+1 -> 45859 | B22: =TEXT(A22,"aaa") -> 月 | C22: ='21'!R51 -> 0 | E22: =SUM(C22,D22) -> 0 | F22: ='21'!R43 -> 0 | G22: ='21'!R44 -> 0 | H22: ='21'!Y5 -> 0 | I22: =SUM('21'!Y7,'21'!Y9,'21'!Y11,'21'!Y13,'21'!Y15,'21'!Y17,'21'!Y19) -> 0 | J22: ='21'!W7 -> 0 | K22: ='21'!W9 -> 0 | L22: ='21'!W11 -> 0 | M22: ='21'!W13 -> 0 | N22: ='21'!W15 -> 0 | O22: ='21'!W17 -> 0 | P22: ='21'!Z5 -> 0 | Q22: ='21'!Z7 -> 0 | R22: ='21'!Z9 -> 0 | S22: ='21'!Z11 -> 0 | T22: ='21'!Z13 -> 0 | U22: ='21'!Z15 -> 0 | V22: ='21'!Z17 -> 0 | W22: ='21'!Z19 -> 0 | X22: ='21'!Z21 -> 0 | Y22: ='21'!Z23 -> 0 | Z22: ='21'!Z25 -> 0 | AA22: ='21'!AA5 -> 0 | AB22: ='21'!AA7 -> 0 | AC22: =SUM('21'!X5,'21'!X7) -> 0 | AD22: ='21'!X9 -> 0 | AE22: =SUM('21'!X11,'21'!X13,'21'!X15,'21'!X17,'21'!X19,'21'!X21) -> 0 | AF22: ='21'!AB4 -> 0 | AG22: ='21'!AB6 -> 0 | AH22: ='21'!AB8 -> 0 | AJ22: 20 | AK22: =HYPERLINK("#"&AJ22&"!A1",AJ22) -> 20
A23: =A22+1 -> 45860 | B23: =TEXT(A23,"aaa") -> 火 | C23: ='22'!R51 -> 0 | E23: =SUM(C23,D23) -> 0 | F23: ='22'!R43 -> 0 | G23: ='22'!R44 -> 0 | H23: ='22'!Y5 -> 0 | I23: =SUM('22'!Y7,'22'!Y9,'22'!Y11,'22'!Y13,'22'!Y15,'22'!Y17,'22'!Y19) -> 0 | J23: ='22'!W7 -> 0 | K23: ='22'!W9 -> 0 | L23: ='22'!W11 -> 0 | M23: ='22'!W13 -> 0 | N23: ='22'!W15 -> 0 | O23: ='22'!W17 -> 0 | P23: ='22'!Z5 -> 0 | Q23: ='22'!Z7 -> 0 | R23: ='22'!Z9 -> 0 | S23: ='22'!Z11 -> 0 | T23: ='22'!Z13 -> 0 | U23: ='22'!Z15 -> 0 | V23: ='22'!Z17 -> 0 | W23: ='22'!Z19 -> 0 | X23: ='22'!Z21 -> 0 | Y23: ='22'!Z23 -> 0 | Z23: ='22'!Z25 -> 0 | AA23: ='22'!AA5 -> 0 | AB23: ='22'!AA7 -> 0 | AC23: =SUM('22'!X5,'22'!X7) -> 0 | AD23: ='22'!X9 -> 0 | AE23: =SUM('22'!X11,'22'!X13,'22'!X15,'22'!X17,'22'!X19,'22'!X21) -> 0 | AF23: ='22'!AB4 -> 0 | AG23: ='22'!AB6 -> 0 | AH23: ='22'!AB8 -> 0 | AJ23: 21 | AK23: =HYPERLINK("#"&AJ23&"!A1",AJ23) -> 21
A24: =A23+1 -> 45861 | B24: =TEXT(A24,"aaa") -> 水 | C24: ='23'!R51 -> 0 | E24: =SUM(C24,D24) -> 0 | F24: ='23'!R43 -> 0 | G24: ='23'!R44 -> 0 | H24: ='23'!Y5 -> 0 | I24: =SUM('23'!Y7,'23'!Y9,'23'!Y11,'23'!Y13,'23'!Y15,'23'!Y17,'23'!Y19) -> 0 | J24: ='23'!W7 -> 0 | K24: ='23'!W9 -> 0 | L24: ='23'!W11 -> 0 | M24: ='23'!W13 -> 0 | N24: ='23'!W15 -> 0 | O24: ='23'!W17 -> 0 | P24: ='23'!Z5 -> 0 | Q24: ='23'!Z7 -> 0 | R24: ='23'!Z9 -> 0 | S24: ='23'!Z11 -> 0 | T24: ='23'!Z13 -> 0 | U24: ='23'!Z15 -> 0 | V24: ='23'!Z17 -> 0 | W24: ='23'!Z19 -> 0 | X24: ='23'!Z21 -> 0 | Y24: ='23'!Z23 -> 0 | Z24: ='23'!Z25 -> 0 | AA24: ='23'!AA5 -> 0 | AB24: ='23'!AA7 -> 0 | AC24: =SUM('23'!X5,'23'!X7) -> 0 | AD24: ='23'!X9 -> 0 | AE24: =SUM('23'!X11,'23'!X13,'23'!X15,'23'!X17,'23'!X19,'23'!X21) -> 0 | AF24: ='23'!AB4 -> 0 | AG24: ='23'!AB6 -> 0 | AH24: ='23'!AB8 -> 0 | AJ24: 22 | AK24: =HYPERLINK("#"&AJ24&"!A1",AJ24) -> 22
A25: =A24+1 -> 45862 | B25: =TEXT(A25,"aaa") -> 木 | C25: ='24'!R51 -> 0 | E25: =SUM(C25,D25) -> 0 | F25: ='24'!R43 -> 0 | G25: ='24'!R44 -> 0 | H25: ='24'!Y5 -> 0 | I25: =SUM('24'!Y7,'24'!Y9,'24'!Y11,'24'!Y13,'24'!Y15,'24'!Y17,'24'!Y19) -> 0 | J25: ='24'!W7 -> 0 | K25: ='24'!W9 -> 0 | L25: ='24'!W11 -> 0 | M25: ='24'!W13 -> 0 | N25: ='24'!W15 -> 0 | O25: ='24'!W17 -> 0 | P25: ='24'!Z5 -> 0 | Q25: ='24'!Z7 -> 0 | R25: ='24'!Z9 -> 0 | S25: ='24'!Z11 -> 0 | T25: ='24'!Z13 -> 0 | U25: ='24'!Z15 -> 0 | V25: ='24'!Z17 -> 0 | W25: ='24'!Z19 -> 0 | X25: ='24'!Z21 -> 0 | Y25: ='24'!Z23 -> 0 | Z25: ='24'!Z25 -> 0 | AA25: ='24'!AA5 -> 0 | AB25: ='24'!AA7 -> 0 | AC25: =SUM('24'!X5,'24'!X7) -> 0 | AD25: ='24'!X9 -> 0 | AE25: =SUM('24'!X11,'24'!X13,'24'!X15,'24'!X17,'24'!X19,'24'!X21) -> 0 | AF25: ='24'!AB4 -> 0 | AG25: ='24'!AB6 -> 0 | AH25: ='24'!AB8 -> 0 | AJ25: 23 | AK25: =HYPERLINK("#"&AJ25&"!A1",AJ25) -> 23
A26: =A25+1 -> 45863 | B26: =TEXT(A26,"aaa") -> 金 | C26: ='25'!R51 -> 0 | E26: =SUM(C26,D26) -> 0 | F26: ='25'!R43 -> 0 | G26: ='25'!R44 -> 0 | H26: ='25'!Y5 -> 0 | I26: =SUM('25'!Y7,'25'!Y9,'25'!Y11,'25'!Y13,'25'!Y15,'25'!Y17,'25'!Y19) -> 0 | J26: ='25'!W7 -> 0 | K26: ='25'!W9 -> 0 | L26: ='25'!W11 -> 0 | M26: ='25'!W13 -> 0 | N26: ='25'!W15 -> 0 | O26: ='25'!W17 -> 0 | P26: ='25'!Z5 -> 0 | Q26: ='25'!Z7 -> 0 | R26: ='25'!Z9 -> 0 | S26: ='25'!Z11 -> 0 | T26: ='25'!Z13 -> 0 | U26: ='25'!Z15 -> 0 | V26: ='25'!Z17 -> 0 | W26: ='25'!Z19 -> 0 | X26: ='25'!Z21 -> 0 | Y26: ='25'!Z23 -> 0 | Z26: ='25'!Z25 -> 0 | AA26: ='25'!AA5 -> 0 | AB26: ='25'!AA7 -> 0 | AC26: =SUM('25'!X5,'25'!X7) -> 0 | AD26: ='25'!X9 -> 0 | AE26: =SUM('25'!X11,'25'!X13,'25'!X15,'25'!X17,'25'!X19,'25'!X21) -> 0 | AF26: ='25'!AB4 -> 0 | AG26: ='25'!AB6 -> 0 | AH26: ='25'!AB8 -> 0 | AJ26: 24 | AK26: =HYPERLINK("#"&AJ26&"!A1",AJ26) -> 24
A27: =A26+1 -> 45864 | B27: =TEXT(A27,"aaa") -> 土 | C27: ='26'!R51 -> 0 | E27: =SUM(C27,D27) -> 0 | F27: ='26'!R43 -> 0 | G27: ='26'!R44 -> 0 | H27: ='26'!Y5 -> 0 | I27: =SUM('26'!Y7,'26'!Y9,'26'!Y11,'26'!Y13,'26'!Y15,'26'!Y17,'26'!Y19) -> 0 | J27: ='26'!W7 -> 0 | K27: ='26'!W9 -> 0 | L27: ='26'!W11 -> 0 | M27: ='26'!W13 -> 0 | N27: ='26'!W15 -> 0 | O27: ='26'!W17 -> 0 | P27: ='26'!Z5 -> 0 | Q27: ='26'!Z7 -> 0 | R27: ='26'!Z9 -> 0 | S27: ='26'!Z11 -> 0 | T27: ='26'!Z13 -> 0 | U27: ='26'!Z15 -> 0 | V27: ='26'!Z17 -> 0 | W27: ='26'!Z19 -> 0 | X27: ='26'!Z21 -> 0 | Y27: ='26'!Z23 -> 0 | Z27: ='26'!Z25 -> 0 | AA27: ='26'!AA5 -> 0 | AB27: ='26'!AA7 -> 0 | AC27: =SUM('26'!X5,'26'!X7) -> 0 | AD27: ='26'!X9 -> 0 | AE27: =SUM('26'!X11,'26'!X13,'26'!X15,'26'!X17,'26'!X19,'26'!X21) -> 0 | AF27: ='26'!AB4 -> 0 | AG27: ='26'!AB6 -> 0 | AH27: ='26'!AB8 -> 0 | AJ27: 25 | AK27: =HYPERLINK("#"&AJ27&"!A1",AJ27) -> 25
A28: =A27+1 -> 45865 | B28: =TEXT(A28,"aaa") -> 日 | C28: ='27'!R51 -> 0 | E28: =SUM(C28,D28) -> 0 | F28: ='27'!R43 -> 0 | G28: ='27'!R44 -> 0 | H28: ='27'!Y5 -> 0 | I28: =SUM('27'!Y7,'27'!Y9,'27'!Y11,'27'!Y13,'27'!Y15,'27'!Y17,'27'!Y19) -> 0 | J28: ='27'!W7 -> 0 | K28: ='27'!W9 -> 0 | L28: ='27'!W11 -> 0 | M28: ='27'!W13 -> 0 | N28: ='27'!W15 -> 0 | O28: ='27'!W17 -> 0 | P28: ='27'!Z5 -> 0 | Q28: ='27'!Z7 -> 0 | R28: ='27'!Z9 -> 0 | S28: ='27'!Z11 -> 0 | T28: ='27'!Z13 -> 0 | U28: ='27'!Z15 -> 0 | V28: ='27'!Z17 -> 0 | W28: ='27'!Z19 -> 0 | X28: ='27'!Z21 -> 0 | Y28: ='27'!Z23 -> 0 | Z28: ='27'!Z25 -> 0 | AA28: ='27'!AA5 -> 0 | AB28: ='27'!AA7 -> 0 | AC28: =SUM('27'!X5,'27'!X7) -> 0 | AD28: ='27'!X9 -> 0 | AE28: =SUM('27'!X11,'27'!X13,'27'!X15,'27'!X17,'27'!X19,'27'!X21) -> 0 | AF28: ='27'!AB4 -> 0 | AG28: ='27'!AB6 -> 0 | AH28: ='27'!AB8 -> 0 | AJ28: 26 | AK28: =HYPERLINK("#"&AJ28&"!A1",AJ28) -> 26
A29: =A28+1 -> 45866 | B29: =TEXT(A29,"aaa") -> 月 | C29: ='28'!R51 -> 0 | E29: =SUM(C29,D29) -> 0 | F29: ='28'!R43 -> 0 | G29: ='28'!R44 -> 0 | H29: ='28'!Y5 -> 0 | I29: =SUM('28'!Y7,'28'!Y9,'28'!Y11,'28'!Y13,'28'!Y15,'28'!Y17,'28'!Y19) -> 0 | J29: ='28'!W7 -> 0 | K29: ='28'!W9 -> 0 | L29: ='28'!W11 -> 0 | M29: ='28'!W13 -> 0 | N29: ='28'!W15 -> 0 | O29: ='28'!W17 -> 0 | P29: ='28'!Z5 -> 0 | Q29: ='28'!Z7 -> 0 | R29: ='28'!Z9 -> 0 | S29: ='28'!Z11 -> 0 | T29: ='28'!Z13 -> 0 | U29: ='28'!Z15 -> 0 | V29: ='28'!Z17 -> 0 | W29: ='28'!Z19 -> 0 | X29: ='28'!Z21 -> 0 | Y29: ='28'!Z23 -> 0 | Z29: ='28'!Z25 -> 0 | AA29: ='28'!AA5 -> 0 | AB29: ='28'!AA7 -> 0 | AC29: =SUM('28'!X5,'28'!X7) -> 0 | AD29: ='28'!X9 -> 0 | AE29: =SUM('28'!X11,'28'!X13,'28'!X15,'28'!X17,'28'!X19,'28'!X21) -> 0 | AF29: ='28'!AB4 -> 0 | AG29: ='28'!AB6 -> 0 | AH29: ='28'!AB8 -> 0 | AJ29: 27 | AK29: =HYPERLINK("#"&AJ29&"!A1",AJ29) -> 27
A30: =A29+1 -> 45867 | B30: =TEXT(A30,"aaa") -> 火 | C30: ='29'!R51 -> 0 | E30: =SUM(C30,D30) -> 0 | F30: ='29'!R43 -> 0 | G30: ='29'!R44 -> 0 | H30: ='29'!Y5 -> 0 | I30: =SUM('29'!Y7,'29'!Y9,'29'!Y11,'29'!Y13,'29'!Y15,'29'!Y17,'29'!Y19) -> 0 | J30: ='29'!W7 -> 0 | K30: ='29'!W9 -> 0 | L30: ='29'!W11 -> 0 | M30: ='29'!W13 -> 0 | N30: ='29'!W15 -> 0 | O30: ='29'!W17 -> 0 | P30: ='29'!Z5 -> 0 | Q30: ='29'!Z7 -> 0 | R30: ='29'!Z9 -> 0 | S30: ='29'!Z11 -> 0 | T30: ='29'!Z13 -> 0 | U30: ='29'!Z15 -> 0 | V30: ='29'!Z17 -> 0 | W30: ='29'!Z19 -> 0 | X30: ='29'!Z21 -> 0 | Y30: ='29'!Z23 -> 0 | Z30: ='29'!Z25 -> 0 | AA30: ='29'!AA5 -> 0 | AB30: ='29'!AA7 -> 0 | AC30: =SUM('29'!X5,'29'!X7) -> 0 | AD30: ='29'!X9 -> 0 | AE30: =SUM('29'!X11,'29'!X13,'29'!X15,'29'!X17,'29'!X19,'29'!X21) -> 0 | AF30: ='29'!AB4 -> 0 | AG30: ='29'!AB6 -> 0 | AH30: ='29'!AB8 -> 0 | AJ30: 28 | AK30: =HYPERLINK("#"&AJ30&"!A1",AJ30) -> 28
A31: =A30+1 -> 45868 | B31: =TEXT(A31,"aaa") -> 水 | C31: ='30'!R51 -> 0 | E31: =SUM(C31,D31) -> 0 | F31: ='30'!R43 -> 0 | G31: ='30'!R44 -> 0 | H31: ='30'!Y5 -> 0 | I31: =SUM('30'!Y7,'30'!Y9,'30'!Y11,'30'!Y13,'30'!Y15,'30'!Y17,'30'!Y19) -> 0 | J31: ='30'!W7 -> 0 | K31: ='30'!W9 -> 0 | L31: ='30'!W11 -> 0 | M31: ='30'!W13 -> 0 | N31: ='30'!W15 -> 0 | O31: ='30'!W17 -> 0 | P31: ='30'!Z5 -> 0 | Q31: ='30'!Z7 -> 0 | R31: ='30'!Z9 -> 0 | S31: ='30'!Z11 -> 0 | T31: ='30'!Z13 -> 0 | U31: ='30'!Z15 -> 0 | V31: ='30'!Z17 -> 0 | W31: ='30'!Z19 -> 0 | X31: ='30'!Z21 -> 0 | Y31: ='30'!Z23 -> 0 | Z31: ='30'!Z25 -> 0 | AA31: ='30'!AA5 -> 0 | AB31: ='30'!AA7 -> 0 | AC31: =SUM('30'!X5,'30'!X7) -> 0 | AD31: ='30'!X9 -> 0 | AE31: =SUM('30'!X11,'30'!X13,'30'!X15,'30'!X17,'30'!X19,'30'!X21) -> 0 | AF31: ='30'!AB4 -> 0 | AG31: ='30'!AB6 -> 0 | AH31: ='30'!AB8 -> 0 | AJ31: 29 | AK31: =HYPERLINK("#"&AJ31&"!A1",AJ31) -> 29
A32: =A31+1 -> 45869 | B32: =TEXT(A32,"aaa") -> 木 | C32: ='31'!R51 -> 0 | E32: =SUM(C32,D32) -> 0 | F32: ='31'!R43 -> 0 | G32: ='31'!R44 -> 0 | H32: ='31'!Y5 -> 0 | I32: =SUM('31'!Y7,'31'!Y9,'31'!Y11,'31'!Y13,'31'!Y15,'31'!Y17,'31'!Y19) -> 0 | J32: ='31'!W7 -> 0 | K32: ='31'!W9 -> 0 | L32: ='31'!W11 -> 0 | M32: ='31'!W13 -> 0 | N32: ='31'!W15 -> 0 | O32: ='31'!W17 -> 0 | P32: ='31'!Z5 -> 0 | Q32: ='31'!Z7 -> 0 | R32: ='31'!Z9 -> 0 | S32: ='31'!Z11 -> 0 | T32: ='31'!Z13 -> 0 | U32: ='31'!Z15 -> 0 | V32: ='31'!Z17 -> 0 | W32: ='31'!Z19 -> 0 | X32: ='31'!Z21 -> 0 | Y32: ='31'!Z23 -> 0 | Z32: ='31'!Z25 -> 0 | AA32: ='31'!AA5 -> 0 | AB32: ='31'!AA7 -> 0 | AC32: =SUM('31'!X5,'31'!X7) -> 0 | AD32: ='31'!X9 -> 0 | AE32: =SUM('31'!X11,'31'!X13,'31'!X15,'31'!X17,'31'!X19,'31'!X21) -> 0 | AF32: ='31'!AB4 -> 0 | AG32: ='31'!AB6 -> 0 | AH32: ='31'!AB8 -> 0 | AJ32: 30 | AK32: =HYPERLINK("#"&AJ32&"!A1",AJ32) -> 30
A33: 合計 | C33: =SUM(C2:C32) -> 0 | D33: =SUM(D2:D32) -> 0 | E33: =SUM(E2:E32) -> 0 | F33: =SUM(F2:F32) -> 0 | G33: =SUM(G2:G32) -> 0 | H33: =SUM(H2:H32) -> 0 | I33: =SUM(I2:I32) -> 0 | J33: =SUM(J2:J32) -> 0 | ... AH33: =SUM(AH2:AH32) -> 0 | AJ33: 31 | AK33: =HYPERLINK("#"&AJ33&"!A1",AJ33) -> 31
A35: 年 | B35: 月
A36: 2025 | B36: 7

Sheet 原本
A1: 日計表 | C1: 令和6年 月 日 ()
B2: 氏名 | C2: 担 | D2: 施術 | E2: 時間 | F2: 保険 | G2: 自費 | H2: 材料費 | I2: 合計 | J2: 支払 | K2: 予約 | L2: 来院 | M2: 年齢 | N2: 性 | O2: 備考 | Q2: 保険売上
A3: 1 | I3: =SUM(F3,G3,H3) -> 0 | Q3: 500 | R3: =SUMIF($F$3:$F$42,Q3,$F$3:$F$42) -> 0 | V3: 自費 | W3: 時間 | X3: 来院 | Y3: 年齢比 | Z3: 男女比 | AA3: 午前 | AC3: 目次 | AD3: シート | AF3: 担当 | AG3: 施術 | AH3: 時間 | AI3: 予約 | AJ3: 料金 | AK3: 延・材 | AL3: 支払 | AM3: 年齢 | AN3: 性別 | AO3: 来院 | AP3: 備考
A4: 2 | I4: =SUM(F4,G4,H4) -> 0 | Q4: 600 | R4: =SUMIF($F$3:$F$42,Q4,$F$3:$F$42) -> 0 | V4: 保険 | W4: 15 | X4: 初 | Y4: 15下 | Z4: 男 | AC4: 月データ | AD4: =HYPERLINK("#"&AC4&"!A1",AC4) -> 月データ | AF4: 時 | AG4: 保険 | AH4: 15 | AI4: 有 | AJ4: 保険 | AK4: 材料 | AL4: 電 | AM4: 15下 | AN4: 男 | AO4: 初 | AP4: キャンペーン
A5: 3 | I5: =SUM(F5,G5,H5) -> 0 | Q5: 800 | R5: =SUMIF($F$3:$F$42,Q5,$F$3:$F$42) -> 0 | V5: =COUNTIF($D$3:$D$42,V4) -> 0 | W5: =COUNTIF($E$3:$E$42,W4) -> 0 | X5: =COUNTIF($L$3:$L$42,AO4) -> 0 | Y5: =COUNTIF($M$3:$M$42,Y4) -> 0 | Z5: =COUNTIF($N$3:$N$42,Z4) -> 0 | AA5: 午後 | AC5: 1 | AD5: =HYPERLINK("#"&AC5&"!A1",AC5) -> 1 | AF5: 上 | AG5: 保延 | AH5: 20 | AI5: 無 | AJ5: 0 | AK5: 300 | AM5: 高 | AN5: 女 | AO5: 再 | AP5: 自賠¥3500
A6: 4 | I6: =SUM(F6,G6,H6) -> 0 | Q6: 1500 | R6: =SUMIF($F$3:$F$42,Q6,$F$3:$F$42) -> 0 | V6: MT | W6: 20 | X6: 再 | Y6: 高 | Z6: 女 | AC6: 2 | AD6: =HYPERLINK("#"&AC6&"!A1",AC6) -> 2 | AF6: 出 | AG6: MT | AH6: 30 | AJ6: 500 | AK6: 500 | AM6: 大 | AO6: 2 | AP6: 助成
A7: 5 | I7: =SUM(F7,G7,H7) -> 0 | Q7: 1600 | R7: =SUMIF($F$3:$F$42,Q7,$F$3:$F$42) -> 0 | V7: =COUNTIF($D$3:$D$42,V6) -> 0 | W7: =COUNTIF($E$3:$E$42,W6) -> 0 | X7: =COUNTIF($L$3:$L$42,AO5) -> 0 | Y7: =COUNTIF($M$3:$M$42,Y6) -> 0 | Z7: =COUNTIF($N$3:$N$42,Z6) -> 0 | AA7: 夕以降 | AC7: 3 | AD7: =HYPERLINK("#"&AC7&"!A1",AC7) -> 3 | AG7: P・深層 | AH7: 40 | AJ7: 600 | AK7: 800 | AM7: 20代 | AO7: 3
A8: 6 | I8: =SUM(F8,G8,H8) -> 0 | Q8: 1800 | R8: =SUMIF($F$3:$F$42,Q8,$F$3:$F$42) -> 0 | V8: P・深層 | W8: 30 | X8: 2 | Y8: 大 | AC8: 4 | AD8: =HYPERLINK("#"&AC8&"!A1",AC8) -> 4 | AG8: B・コン | AH8: 50 | AJ8: 800 | AM8: 30代 | AO8: 4
A9: 7 | I9: =SUM(F9,G9,H9) -> 0 | Q9: 計 | R9: =SUM(R3:R8) -> 0 | V9: =COUNTIF($D$3:$D$42,V8) -> 0 | W9: =COUNTIF($E$3:$E$42,W8) -> 0 | X9: =COUNTIF($L$3:$L$42,AO6) -> 0 | Y9: =COUNTIF($M$3:$M$42,Y8) -> 0 | AC9: 5 | AD9: =HYPERLINK("#"&AC9&"!A1",AC9) -> 5 | AG9: I・コン | AH9: 60 | AJ9: 初診 | AM9: 40代 | AO9: 5上
A10: 8 | I10: =SUM(F10,G10,H10) -> 0 | V10: B・コン | W10: 40 | X10: 3 | Y10: 20代 | AC10: 6 | AD10: =HYPERLINK("#"&AC10&"!A1",AC10) -> 6 | AG10: 産後 | AH10: 70 | AJ10: 1500 | AM10: 50代 | AO10: 10上
A11: 9 | I11: =SUM(F11,G11,H11) -> 0 | Q11: 自費売上 | V11: =COUNTIF($D$3:$D$42,V10) -> 0 | W11: =COUNTIF($E$3:$E$42,W10) -> 0 | X11: =COUNTIF($L$3:$L$42,AO7) -> 0 | Y11: =COUNTIF($M$3:$M$42,Y10) -> 0 | AC11: 7 | AD11: =HYPERLINK("#"&AC11&"!A1",AC11) -> 7 | AG11: 自賠責 | AH11: 80 | AJ11: 1600 | AM11: 60代 | AO11: 20上
A12: 10 | I12: =SUM(F12,G12,H12) -> 0 | Q12: 1000 | R12: =SUMIF($G$3:$G$42,Q12,$G$3:$G$42) -> 0 | V12: I・コン | W12: 50 | X12: 4 | Y12: 30代 | AC12: 8 | AD12: =HYPERLINK("#"&AC12&"!A1",AC12) -> 8 | AH12: 90 | AJ12: 1800 | AM12: 70代 | AO12: 週1
A13: 11 | I13: =SUM(F13,G13,H13) -> 0 | Q13: 2000 | R13: =SUMIF($G$3:$G$42,Q13,$G$3:$G$42) -> 0 | V13: =COUNTIF($D$3:$D$42,V12) -> 0 | W13: =COUNTIF($E$3:$E$42,W12) -> 0 | X13: =COUNTIF($L$3:$L$42,AO8) -> 0 | Y13: =COUNTIF($M$3:$M$42,Y12) -> 0 | AC13: 9 | AD13: =HYPERLINK("#"&AC13&"!A1",AC13) -> 9 | AJ13: 自費1 | AM13: 80代 | AO13: 週2
A14: 12 | I14: =SUM(F14,G14,H14) -> 0 | Q14: 3000 | R14: =SUMIF($G$3:$G$42,Q14,$G$3:$G$42) -> 0 | V14: 産後 | W14: 60 | X14: 5上 | Y14: 40代 | AC14: 10 | AD14: =HYPERLINK("#"&AC14&"!A1",AC14) -> 10 | AJ14: 1000 | AM14: 90代 | AO14: 週3
A15: 13 | I15: =SUM(F15,G15,H15) -> 0 | Q15: 4000 | R15: =SUMIF($G$3:$G$42,Q15,$G$3:$G$42) -> 0 | V15: =COUNTIF($D$3:$D$42,V14) -> 0 | W15: =COUNTIF($E$3:$E$42,W14) -> 0 | X15: =COUNTIF($L$3:$L$42,AO9) -> 0 | Y15: =COUNTIF($M$3:$M$42,Y14) -> 0 | AC15: 11 | AD15: =HYPERLINK("#"&AC15&"!A1",AC15) -> 11 | AJ15: 2000 | AO15: 毎
A16: 14 | I16: =SUM(F16,G16,H16) -> 0 | Q16: 5000 | R16: =SUMIF($G$3:$G$42,Q16,$G$3:$G$42) -> 0 | V16: 保延 | W16: 70 | X16: 10上 | Y16: 50代 | AC16: 12 | AD16: =HYPERLINK("#"&AC16&"!A1",AC16) -> 12 | AG16: 2800 | AH16: 30 | AJ16: 3000 | AO16: 1/2W
A17: 15 | I17: =SUM(F17,G17,H17) -> 0 | Q17: 6000 | R17: =SUMIF($G$3:$G$42,Q17,$G$3:$G$42) -> 0 | V17: =COUNTIF(D3:D42,V16) -> 0 | W17: =COUNTIF($E$3:$E$42,W16) -> 0 | X17: =COUNTIF($L$3:$L$42,AO10) -> 0 | Y17: =COUNTIF($M$3:$M$42,Y16) -> 0 | AC17: 13 | AD17: =HYPERLINK("#"&AC17&"!A1",AC17) -> 13 | AG17: 5500 | AH17: 60 | AJ17: 4000 | AO17: 1/3W
A18: 16 | I18: =SUM(F18,G18,H18) -> 0 | Q18: 7000 | R18: =SUMIF($G$3:$G$42,Q18,$G$3:$G$42) -> 0 | W18: 80 | X18: 20上 | Y18: 60代 | AC18: 14 | AD18: =HYPERLINK("#"&AC18&"!A1",AC18) -> 14 | AG18: 7800 | AH18: 90 | AJ18: 5000 | AO18: 月1
A19: 17 | I19: =SUM(F19,G19,H19) -> 0 | Q19: 8000 | R19: =SUMIF($G$3:$G$42,Q19,$G$3:$G$42) -> 0 | W19: =COUNTIF($E$3:$E$42,W18) -> 0 | X19: =COUNTIF($L$3:$L$42,AO11) -> 0 | Y19: =COUNTIF($M$3:$M$42,Y18) -> 0 | AC19: 15 | AD19: =HYPERLINK("#"&AC19&"!A1",AC19) -> 15 | AJ19: 6000 | AO19: 不
A20: 18 | I20: =SUM(F20,G20,H20) -> 0 | Q20: 9000 | R20: =SUMIF($G$3:$G$42,Q20,$G$3:$G$42) -> 0 | W20: 90 | X20: 毎 | Y20: 70代 | AC20: 16 | AD20: =HYPERLINK("#"&AC20&"!A1",AC20) -> 16 | AJ20: 7000
A21: 19 | I21: =SUM(F21,G21,H21) -> 0 | Q21: 12000 | R21: =SUMIF($G$3:$G$42,Q21,$G$3:$G$42) -> 0 | T21: 時田 | U21: =SUM(U22,U23) -> 0 | W21: =COUNTIF($E$3:$E$42,W20) -> 0 | X21: =COUNTIF($L$3:$L$42,AO15) -> 0 | Y21: =COUNTIF($M$3:$M$42,Y20) -> 0 | AC21: 17 | AD21: =HYPERLINK("#"&AC21&"!A1",AC21) -> 17 | AJ21: 8000
A22: 20 | I22: =SUM(F22,G22,H22) -> 0 | Q22: 1600 | R22: =SUMIF($G$3:$G$42,Q22,$G$3:$G$42) -> 0 | T22: 保険人数 | U22: =COUNTIFS($C$3:$C$42,AF4,$F$3:$F$42,">=0") -> 0 | X22: 週1 | Y22: 80代 | AC22: 18 | AD22: =HYPERLINK("#"&AC22&"!A1",AC22) -> 18 | AJ22: 9000
A23: 21 | I23: =SUM(F23,G23,H23) -> 0 | Q23: 2600 | R23: =SUMIF($G$3:$G$42,Q23,$G$3:$G$42) -> 0 | T23: 自費人数 | U23: =(COUNTIFS($C:$C,AF4,$D:$D,$AG$6))+(COUNTIFS($C:$C,AF4,$D:$D,$AG$7))+(COUNTIFS($C:$C,AF4,$D:$D,AG8))+(COUNTIFS($C:$C,AF4,$D:$D,AG9)+(COUNTIFS($C:$C,AF4,$D:$D,AG10))) -> 0 | X23: =COUNTIF($L$3:$L$42,AO12) -> 0 | Y23: =COUNTIF($M$3:$M$42,Y22) -> 0 | AC23: 19 | AD23: =HYPERLINK("#"&AC23&"!A1",AC23) -> 19 | AJ23: 12000
A24: 22 | I24: =SUM(F24,G24,H24) -> 0 | Q24: 3600 | R24: =SUMIF($G$3:$G$42,Q24,$G$3:$G$42) -> 0 | T24: 自費売上 | U24: =SUMIF($C:$C,AF4,$G:$G) -> 0 | X24: 週2 | Y24: 90代 | AC24: 20 | AD24: =HYPERLINK("#"&AC24&"!A1",AC24) -> 20 | AJ24: 自費2
A25: 23 | I25: =SUM(F25,G25,H25) -> 0 | Q25: 4600 | R25: =SUMIF($G$3:$G$42,Q25,$G$3:$G$42) -> 0 | X25: =COUNTIF($L$3:$L$42,AO13) -> 0 | Y25: =COUNTIF($M$3:$M$42,Y24) -> 0 | AC25: 21 | AD25: =HYPERLINK("#"&AC25&"!A1",AC25) -> 21 | AJ25: 1600
A26: 24 | I26: =SUM(F26,G26,H26) -> 0 | Q26: 5600 | R26: =SUMIF($G$3:$G$42,Q26,$G$3:$G$42) -> 0 | T26: 上田 | U26: =SUM(U27,U28) -> 0 | X26: 週3 | AC26: 22 | AD26: =HYPERLINK("#"&AC26&"!A1",AC26) -> 22 | AJ26: 2600
A27: 25 | I27: =SUM(F27,G27,H27) -> 0 | Q27: 6600 | R27: =SUMIF($G$3:$G$42,Q27,$G$3:$G$42) -> 0 | T27: 保険人数 | U27: =COUNTIFS($C$3:$C$42,AF5,$F$3:$F$42,">=0") -> 0 | X27: =COUNTIF($L$3:$L$42,AO14) -> 0 | AC27: 23 | AD27: =HYPERLINK("#"&AC27&"!A1",AC27) -> 23 | AJ27: 3600
A28: 26 | I28: =SUM(F28,G28,H28) -> 0 | Q28: 7600 | R28: =SUMIF($G$3:$G$42,Q28,$G$3:$G$42) -> 0 | T28: 自費人数 | U28: =(COUNTIFS($C:$C,AF5,$D:$D,$AG$6))+(COUNTIFS($C:$C,AF5,$D:$D,$AG$7))+(COUNTIFS($C:$C,AF5,$D:$D,AG8))+(COUNTIFS($C:$C,AF5,$D:$D,AG9)+(COUNTIFS($C:$C,AF5,$D:$D,AG10))) -> 0 | X28: 1/2W | AC28: 24 | AD28: =HYPERLINK("#"&AC28&"!A1",AC28) -> 24 | AJ28: 4600
A29: 27 | I29: =SUM(F29,G29,H29) -> 0 | Q29: 8600 | R29: =SUMIF($G$3:$G$42,Q29,$G$3:$G$42) -> 0 | T29: 自費売上 | U29: =SUMIF($C:$C,AF5,$G:$G) -> 0 | X29: =COUNTIF($L$3:$L$42,AO16) -> 0 | AC29: 25 | AD29: =HYPERLINK("#"&AC29&"!A1",AC29) -> 25 | AJ29: 5600
A30: 28 | I30: =SUM(F30,G30,H30) -> 0 | Q30: 9600 | R30: =SUMIF($G$3:$G$42,Q30,$G$3:$G$42) -> 0 | X30: 1/3W | AC30: 26 | AD30: =HYPERLINK("#"&AC30&"!A1",AC30) -> 26 | AJ30: 6600
A31: 29 | I31: =SUM(F31,G31,H31) -> 0 | Q31: 2500 | R31: =SUMIF($G$3:$G$42,Q31,$G$3:$G$42) -> 0 | T31: 出口 | U31: =SUM(U32,U33) -> 0 | X31: =COUNTIF($L$3:$L$42,AO17) -> 0 | AC31: 27 | AD31: =HYPERLINK("#"&AC31&"!A1",AC31) -> 27 | AJ31: 7600
A32: 30 | I32: =SUM(F32,G32,H32) -> 0 | Q32: 3800 | R32: =SUMIF($G$3:$G$42,Q32,$G$3:$G$42) -> 0 | T32: 保険人数 | U32: =COUNTIFS($C$3:$C$42,AF6,$F$3:$F$42,">=0") -> 0 | X32: 月1 | AC32: 28 | AD32: =HYPERLINK("#"&AC32&"!A1",AC32) -> 28 | AJ32: 8600
A33: 31 | I33: =SUM(F33,G33,H33) -> 0 | Q33: 4500 | R33: =SUM(R12:R32) -> 0 | T33: 自費人数 | U33: =(COUNTIFS($C:$C,AF6,$D:$D,$AG$6))+(COUNTIFS($C:$C,AF6,$D:$D,$AG$7))+(COUNTIFS($C:$C,AF6,$D:$D,AG8))+(COUNTIFS($C:$C,AF6,$D:$D,AG9)+(COUNTIFS($C:$C,AF6,$D:$D,AG10))) -> 0 | X33: =COUNTIF($L$3:$L$42,AO18) -> 0 | AC33: 29 | AD33: =HYPERLINK("#"&AC33&"!A1",AC33) -> 29 | AJ33: 9600
A34: 32 | I34: =SUM(F34,G34,H34) -> 0 | Q34: 計 | R34: =SUM(R12:R33) -> 0 | T34: 自費売上 | U34: =SUMIF($C:$C,AF6,$G:$G) -> 0 | X34: 不 | AC34: 30 | AD34: =HYPERLINK("#"&AC34&"!A1",AC34) -> 30 | AJ34: 自費2
A35: 33 | I35: =SUM(F35,G35,H35) -> 0 | X35: =COUNTIF($L$3:$L$42,AO19) -> 0 | AC35: 31 | AD35: =HYPERLINK("#"&AC35&"!A1",AC35) -> 31 | AJ35: 2500
A36: 34 | I36: =SUM(F36,G36,H36) -> 0 | Q36: 材料費 | AJ36: 4500
A37: 35 | I37: =SUM(F37,G37,H37) -> 0 | Q37: 300 | R37: =SUMIF($H$3:$H$42,Q38,$H$3:$H$42) -> 0 | T37: 総人数 | U37: =SUM(U38,U40) -> 0 | AJ37: 3800
A38: 36 | I38: =SUM(F38,G38,H38) -> 0 | Q38: 500 | R38: =SUMIF($H$3:$H$42,Q39,$H$3:$H$42) -> 0 | T38: 保険 | U38: =COUNTIF($D$3:$D$42,T38)+COUNTIF($D$3:$D$42,AG5) -> 0
A39: 37 | I39: =SUM(F39,G39,H39) -> 0 | Q39: 800 | R39: =SUM(R36:R38) -> 0 | T39: 保険金額 | U39: =SUM(R3:R8) -> 0
A40: 38 | I40: =SUM(F40,G40,H40) -> 0 | Q40: 計 | R40: =SUM(R37:R39) -> 0 | T40: 自費 | U40: =SUM(V40:V42:V40:V42)-W42 -> 0 | V40: =COUNTIFS($C$3:$C$42,AF4,G3:$G$42,">=0") -> 0
...

Sheet 1
A1: 日計表 | C1: 令和8年 月 1日 ()
B2: 氏名 | C2: 担 | D2: 施術 | E2: 時間 | F2: 保険 | G2: 自費 | H2: 材・販 | I2: 合計 | J2: 支払 | K2: 予約 | L2: 来院 | M2: 年齢 | N2: 性 | O2: 備考 | Q2: 保険売上
A3: 1 | I3: =SUM(F3,G3,H3) -> 0 | Q3: 600 | R3: =SUMIF($F$3:$F$42,Q3,$F$3:$F$42) -> 0 | W3: 自費 | X3: 時間 | Y3: 来院 | Z3: 年齢比 | AA3: 男女比 | AB3: 午前 | AD3: 目次 | AE3: シート | AG3: 担当 | AH3: 施術 | AI3: 時間 | AJ3: 予約 | AK3: 料金 | AL3: 延・材 | AM3: 支払 | AN3: 年齢 | AO3: 性別 | AP3: 来院 | AQ3: 備考
A4: 2 | I4: =SUM(F4,G4,H4) -> 0 | Q4: 700 | R4: =SUMIF($F$3:$F$42,Q4,$F$3:$F$42) -> 0 | W4: 保険 | X4: 15 | Y4: 初 | Z4: 15下 | AA4: 男 | AD4: 月データ | AE4: =HYPERLINK("#"&AD4&"!A1",AD4) -> 月データ | AG4: 時 | AH4: 保険 | AI4: 15 | AJ4: 有 | AK4: 保険 | AL4: 材料 | AM4: 電 | AN4: 15下 | AO4: 男 | AP4: 初 | AQ4: キャンペーン
A5: 3 | I5: =SUM(F5,G5,H5) -> 0 | Q5: 900 | R5: =SUMIF($F$3:$F$42,Q5,$F$3:$F$42) -> 0 | W5: =COUNTIF($D$3:$D$42,W4) -> 0 | X5: =COUNTIF($E$3:$E$42,X4) -> 0 | Y5: =COUNTIF($L$3:$L$42,AP4) -> 0 | Z5: =COUNTIF($M$3:$M$42,Z4) -> 0 | AA5: =COUNTIF($N$3:$N$42,AA4) -> 0 | AB5: 午後 | AD5: 1 | AE5: =HYPERLINK("#"&AD5&"!A1",AD5) -> 1 | AG5: 上 | AH5: 保延 | AI5: 20 | AJ5: 無 | AK5: 0 | AL5: 300 | AN5: 高 | AO5: 女 | AP5: 再 | AQ5: 深夜整体
A6: 4 | I6: =SUM(F6,G6,H6) -> 0 | Q6: 1600 | R6: =SUMIF($F$3:$F$42,Q6,$F$3:$F$42) -> 0 | W6: MT | X6: 20 | Y6: 再 | Z6: 高 | AA6: 女 | AD6: 2 | AE6: =HYPERLINK("#"&AD6&"!A1",AD6) -> 2 | AG6: 出 | AH6: MT | AI6: 30 | AK6: 600 | AL6: 500 | AN6: 大 | AP6: 2 | AQ6: 自賠¥3600
A7: 5 | I7: =SUM(F7,G7,H7) -> 0 | Q7: 1700 | R7: =SUMIF($F$3:$F$42,Q7,$F$3:$F$42) -> 0 | W7: =COUNTIF($D$3:$D$42,W6) -> 0 | X7: =COUNTIF($E$3:$E$42,X6) -> 0 | Y7: =COUNTIF($L$3:$L$42,AP5) -> 0 | Z7: =COUNTIF($M$3:$M$42,Z6) -> 0 | AA7: =COUNTIF($N$3:$N$42,AA6) -> 0 | AB7: 夕以降 | AD7: 3 | AE7: =HYPERLINK("#"&AD7&"!A1",AD7) -> 3 | AH7: MT＋I | AI7: 40 | AK7: 700 | AL7: 800 | AN7: 20代 | AP7: 3 | AQ7: 紹介割
A8: 6 | I8: =SUM(F8,G8,H8) -> 0 | Q8: 1900 | R8: =SUMIF($F$3:$F$42,Q8,$F$3:$F$42) -> 0 | W8: P・深層 | X8: 30 | Y8: 2 | Z8: 大 | AD8: 4 | AE8: =HYPERLINK("#"&AD8&"!A1",AD8) -> 4 | AH8: P・深層 | AI8: 50 | AK8: 900 | AN8: 30代 | AP8: 4 | AQ8: 商品券
A9: 7 | I9: =SUM(F9,G9,H9) -> 0 | Q9: 計 | R9: =SUM(R3:R8) -> 0 | W9: =COUNTIF($D$3:$D$42,W8) -> 0 | X9: =COUNTIF($E$3:$E$42,X8) -> 0 | Y9: =COUNTIF($L$3:$L$42,AP6) -> 0 | Z9: =COUNTIF($M$3:$M$42,Z8) -> 0 | AD9: 5 | AE9: =HYPERLINK("#"&AD9&"!A1",AD9) -> 5 | AH9: B・コン | AI9: 60 | AK9: 初診 | AN9: 40代 | AP9: 5上 | AQ9: 助成
A10: 8 | I10: =SUM(F10,G10,H10) -> 0 | W10: B・コン | X10: 40 | Y10: 3 | Z10: 20代 | AD10: 6 | AE10: =HYPERLINK("#"&AD10&"!A1",AD10) -> 6 | AH10: I・コン | AI10: 70 | AK10: 1600 | AN10: 50代 | AP10: 10上
A11: 9 | I11: =SUM(F11,G11,H11) -> 0 | Q11: 自費売上 | W11: =COUNTIF($D$3:$D$42,W10) -> 0 | X11: =COUNTIF($E$3:$E$42,X10) -> 0 | Y11: =COUNTIF($L$3:$L$42,AP7) -> 0 | Z11: =COUNTIF($M$3:$M$42,Z10) -> 0 | AD11: 7 | AE11: =HYPERLINK("#"&AD11&"!A1",AD11) -> 7 | AH11: 産後 | AI11: 80 | AK11: 1700 | AN11: 60代 | AP11: 20上
A12: 10 | I12: =SUM(F12,G12,H12) -> 0 | Q12: 1000 | R12: =SUMIF($G$3:$G$42,Q12,$G$3:$G$42) -> 0 | W12: I・コン | X12: 50 | Y12: 4 | Z12: 30代 | AD12: 8 | AE12: =HYPERLINK("#"&AD12&"!A1",AD12) -> 8 | AH12: 自賠責 | AI12: 90 | AK12: 1900 | AN12: 70代 | AP12: 週1
A13: 11 | I13: =SUM(F13,G13,H13) -> 0 | Q13: 2000 | R13: =SUMIF($G$3:$G$42,Q13,$G$3:$G$42) -> 0 | W13: =COUNTIF($D$3:$D$42,W12) -> 0 | X13: =COUNTIF($E$3:$E$42,X12) -> 0 | Y13: =COUNTIF($L$3:$L$42,AP8) -> 0 | Z13: =COUNTIF($M$3:$M$42,Z12) -> 0 | AD13: 9 | AE13: =HYPERLINK("#"&AD13&"!A1",AD13) -> 9 | AK13: 自費1 | AN13: 80代 | AP13: 週2
A14: 12 | I14: =SUM(F14,G14,H14) -> 0 | Q14: 3000 | R14: =SUMIF($G$3:$G$42,Q14,$G$3:$G$42) -> 0 | W14: 産後 | X14: 60 | Y14: 5上 | Z14: 40代 | AD14: 10 | AE14: =HYPERLINK("#"&AD14&"!A1",AD14) -> 10 | AK14: 1000 | AN14: 90代 | AP14: 週3
A15: 13 | I15: =SUM(F15,G15,H15) -> 0 | Q15: 4000 | R15: =SUMIF($G$3:$G$42,Q15,$G$3:$G$42) -> 0 | W15: =COUNTIF($D$3:$D$42,W14) -> 0 | X15: =COUNTIF($E$3:$E$42,X14) -> 0 | Y15: =COUNTIF($L$3:$L$42,AP9) -> 0 | Z15: =COUNTIF($M$3:$M$42,Z14) -> 0 | AD15: 11 | AE15: =HYPERLINK("#"&AD15&"!A1",AD15) -> 11 | AK15: 2000 | AP15: 毎
A16: 14 | I16: =SUM(F16,G16,H16) -> 0 | Q16: 5000 | R16: =SUMIF($G$3:$G$42,Q16,$G$3:$G$42) -> 0 | W16: 保延 | X16: 70 | Y16: 10上 | Z16: 50代 | AD16: 12 | AE16: =HYPERLINK("#"&AD16&"!A1",AD16) -> 12 | AK16: 3000 | AP16: 1/2W
A17: 15 | I17: =SUM(F17,G17,H17) -> 0 | Q17: 6000 | R17: =SUMIF($G$3:$G$42,Q17,$G$3:$G$42) -> 0 | W17: =COUNTIF(D3:D42,W16) -> 0 | X17: =COUNTIF($E$3:$E$42,X16) -> 0 | Y17: =COUNTIF($L$3:$L$42,AP10) -> 0 | Z17: =COUNTIF($M$3:$M$42,Z16) -> 0 | AD17: 13 | AE17: =HYPERLINK("#"&AD17&"!A1",AD17) -> 13 | AK17: 4000 | AP17: 1/3W
A18: 16 | I18: =SUM(F18,G18,H18) -> 0 | Q18: 7000 | R18: =SUMIF($G$3:$G$42,Q18,$G$3:$G$42) -> 0 | X18: 80 | Y18: 20上 | Z18: 60代 | AD18: 14 | AE18: =HYPERLINK("#"&AD18&"!A1",AD18) -> 14 | AK18: 5000 | AP18: 月1
A19: 17 | I19: =SUM(F19,G19,H19) -> 0 | Q19: 8000 | R19: =SUMIF($G$3:$G$42,Q19,$G$3:$G$42) -> 0 | X19: =COUNTIF($E$3:$E$42,X18) -> 0 | Y19: =COUNTIF($L$3:$L$42,AP11) -> 0 | Z19: =COUNTIF($M$3:$M$42,Z18) -> 0 | AD19: 15 | AE19: =HYPERLINK("#"&AD19&"!A1",AD19) -> 15 | AK19: 6000 | AP19: 不
A20: 18 | I20: =SUM(F20,G20,H20) -> 0 | Q20: 9000 | R20: =SUMIF($G$3:$G$42,Q20,$G$3:$G$42) -> 0 | X20: 90 | Y20: 毎 | Z20: 70代 | AD20: 16 | AE20: =HYPERLINK("#"&AD20&"!A1",AD20) -> 16 | AK20: 7000
A21: 19 | I21: =SUM(F21,G21,H21) -> 0 | Q21: 10000 | R21: =SUMIF($G$3:$G$42,Q21,$G$3:$G$42) -> 0 | T21: 自費売上 | X21: =COUNTIF($E$3:$E$42,X20) -> 0 | Y21: =COUNTIF($L$3:$L$42,AP15) -> 0 | Z21: =COUNTIF($M$3:$M$42,Z20) -> 0 | AD21: 17 | AE21: =HYPERLINK("#"&AD21&"!A1",AD21) -> 17 | AK21: 8000
A22: 20 | I22: =SUM(F22,G22,H22) -> 0 | Q22: 11000 | R22: =SUMIF($G$3:$G$42,Q22,$G$3:$G$42) -> 0 | T22: 2500 | U22: =SUMIF($G$3:$G$42,T22,$G$3:$G$42) -> 0 | Y22: 週1 | Z22: 80代 | AD22: 18 | AE22: =HYPERLINK("#"&AD22&"!A1",AD22) -> 18 | AK22: 9000
A23: 21 | I23: =SUM(F23,G23,H23) -> 0 | Q23: 12000 | R23: =SUMIF($G$3:$G$42,Q23,$G$3:$G$42) -> 0 | T23: 2800 | U23: =SUMIF($G$3:$G$42,T23,$G$3:$G$42) -> 0 | Y23: =COUNTIF($L$3:$L$42,AP12) -> 0 | Z23: =COUNTIF($M$3:$M$42,Z22) -> 0 | AD23: 19 | AE23: =HYPERLINK("#"&AD23&"!A1",AD23) -> 19 | AK23: 10000
A24: 22 | I24: =SUM(F24,G24,H24) -> 0 | Q24: 1700 | R24: =SUMIF($G$3:$G$42,Q24,$G$3:$G$42) -> 0 | T24: 3800 | U24: =SUMIF($G$3:$G$42,T24,$G$3:$G$42) -> 0 | Y24: 週2 | Z24: 90代 | AD24: 20 | AE24: =HYPERLINK("#"&AD24&"!A1",AD24) -> 20 | AK24: 11000
A25: 23 | I25: =SUM(F25,G25,H25) -> 0 | Q25: 2700 | R25: =SUMIF($G$3:$G$42,Q25,$G$3:$G$42) -> 0 | T25: 4500 | U25: =SUMIF($G$3:$G$42,T25,$G$3:$G$42) -> 0 | Y25: =COUNTIF($L$3:$L$42,AP13) -> 0 | Z25: =COUNTIF($M$3:$M$42,Z24) -> 0 | AD25: 21 | AE25: =HYPERLINK("#"&AD25&"!A1",AD25) -> 21 | AK25: 自費2
A26: 24 | I26: =SUM(F26,G26,H26) -> 0 | Q26: 3700 | R26: =SUMIF($G$3:$G$42,Q26,$G$3:$G$42) -> 0 | T26: 5500 | U26: =SUMIF($G$3:$G$42,T26,$G$3:$G$42) -> 0 | Y26: 週3 | AD26: 22 | AE26: =HYPERLINK("#"&AD26&"!A1",AD26) -> 22 | AK26: 1700
A27: 25 | I27: =SUM(F27,G27,H27) -> 0 | Q27: 4700 | R27: =SUMIF($G$3:$G$42,Q27,$G$3:$G$42) -> 0 | T27: 6300 | U27: =SUMIF($G$3:$G$42,T27,$G$3:$G$42) -> 0 | Y27: =COUNTIF($L$3:$L$42,AP14) -> 0 | AD27: 23 | AE27: =HYPERLINK("#"&AD27&"!A1",AD27) -> 23 | AK27: 2700
A28: 26 | I28: =SUM(F28,G28,H28) -> 0 | Q28: 5700 | R28: =SUMIF($G$3:$G$42,Q28,$G$3:$G$42) -> 0 | T28: 7800 | U28: =SUMIF($G$3:$G$42,T28,$G$3:$G$42) -> 0 | Y28: 1/2W | AD28: 24 | AE28: =HYPERLINK("#"&AD28&"!A1",AD28) -> 24 | AK28: 3700
A29: 27 | I29: =SUM(F29,G29,H29) -> 0 | Q29: 6700 | R29: =SUMIF($G$3:$G$42,Q29,$G$3:$G$42) -> 0 | T29: 28000 | U29: =SUMIF($G$3:$G$42,T29,$G$3:$G$42) -> 0 | Y29: =COUNTIF($L$3:$L$42,AP16) -> 0 | AD29: 25 | AE29: =HYPERLINK("#"&AD29&"!A1",AD29) -> 25 | AK29: 4700
A30: 28 | I30: =SUM(F30,G30,H30) -> 0 | Q30: 7700 | R30: =SUMIF($G$3:$G$42,Q30,$G$3:$G$42) -> 0 | T30: 29000 | U30: =SUMIF($G$3:$G$42,T30,$G$3:$G$42) -> 0 | Y30: 1/3W | AD30: 26 | AE30: =HYPERLINK("#"&AD30&"!A1",AD30) -> 26 | AK30: 5700
A31: 29 | I31: =SUM(F31,G31,H31) -> 0 | Q31: 8700 | R31: =SUMIF($G$3:$G$42,Q31,$G$3:$G$42) -> 0 | T31: 35000 | U31: =SUMIF($G$3:$G$42,T31,$G$3:$G$42) -> 0 | Y31: =COUNTIF($L$3:$L$42,AP17) -> 0 | AD31: 27 | AE31: =HYPERLINK("#"&AD31&"!A1",AD31) -> 27 | AK31: 6700
A32: 30 | I32: =SUM(F32,G32,H32) -> 0 | Q32: 9700 | R32: =SUMIF($G$3:$G$42,Q32,$G$3:$G$42) -> 0 | T32: 50000 | U32: =SUMIF($G$3:$G$42,T32,$G$3:$G$42) -> 0 | Y32: 月1 | AD32: 28 | AE32: =HYPERLINK("#"&AD32&"!A1",AD32) -> 28 | AK32: 7700
A33: 31 | I33: =SUM(F33,G33,H33) -> 0 | Q33: 12700 | R33: =SUM(R12:R32) -> 0 | U33: =SUM(U22:U32) -> 0 | Y33: =COUNTIF($L$3:$L$42,AP18) -> 0 | AD33: 29 | AE33: =HYPERLINK("#"&AD33&"!A1",AD33) -> 29 | AK33: 8700
A34: 32 | I34: =SUM(F34,G34,H34) -> 0 | Q34: 計 | R34: =SUM(R12:R33) -> 0 | T34: 計 | U34: =SUM(U22:U33) -> 0 | Y34: 不 | AD34: 30 | AE34: =HYPERLINK("#"&AD34&"!A1",AD34) -> 30 | AK34: 9700
A35: 33 | I35: =SUM(F35,G35,H35) -> 0 | Y35: =COUNTIF($L$3:$L$42,AP19) -> 0 | AD35: 31 | AE35: =HYPERLINK("#"&AD35&"!A1",AD35) -> 31 | AK35: 10700
A36: 34 | I36: =SUM(F36,G36,H36) -> 0 | Q36: 材料費 | AK36: 自費3
A37: 35 | I37: =SUM(F37,G37,H37) -> 0 | Q37: 300 | R37: =SUMIF($H$3:$H$42,Q38,$H$3:$H$42) -> 0 | T37: 時田 | U37: =SUM(U38,U39) -> 0 | AK37: 2500
A38: 36 | I38: =SUM(F38,G38,H38) -> 0 | Q38: 500 | R38: =SUMIF($H$3:$H$42,Q39,$H$3:$H$42) -> 0 | T38: 保険人数 | U38: =COUNTIFS($C$3:$C$42,AG4,$F$3:$F$42,">=0") -> 0 | AK38: 3800
A39: 37 | I39: =SUM(F39,G39,H39) -> 0 | Q39: 800 | R39: =SUMIF($H$3:$H$42,Q39,$H$3:$H$42) -> 0 | T39: 自費人数 | U39: =(COUNTIFS($C:$C,AG4,$D:$D,$AH$6))+(COUNTIFS($C:$C,AG4,$D:$D,$AH$8))+(COUNTIFS($C:$C,AG4,$D:$D,AH9))+(COUNTIFS($C:$C,AG4,$D:$D,AH10)+(COUNTIFS($C:$C,AG4,$D:$D,AH11))) -> 0 | AK39: 4500
A40: 38 | I40: =SUM(F40,G40,H40) -> 0 | R40: =SUMIF($H$3:$H$42,Q40,$H$3:$H$42) -> 0 | T40: 自費売上 | U40: =SUMIF($C:$C,AG4,$G:$G) -> 0 | W40: =COUNTIFS($C$3:$C$42,AG4,G3:$G$42,">=0") -> 0 | AK40: 5800
...

Sheet 2
A1: 日計表 | C1: 令和8年 月 2日 ()
B2: 氏名 | C2: 担 | D2: 施術 | E2: 時間 | F2: 保険 | G2: 自費 | H2: 材・販 | I2: 合計 | J2: 支払 | K2: 予約 | L2: 来院 | M2: 年齢 | N2: 性 | O2: 備考 | Q2: 保険売上
A3: 1 | I3: =SUM(F3,G3,H3) -> 0 | Q3: 600 | R3: =SUMIF($F$3:$F$42,Q3,$F$3:$F$42) -> 0 | W3: 自費 | X3: 時間 | Y3: 来院 | Z3: 年齢比 | AA3: 男女比 | AB3: 午前 | AD3: 目次 | AE3: シート | AG3: 担当 | AH3: 施術 | AI3: 時間 | AJ3: 予約 | AK3: 料金 | AL3: 延・材 | AM3: 支払 | AN3: 年齢 | AO3: 性別 | AP3: 来院 | AQ3: 備考
A4: 2 | I4: =SUM(F4,G4,H4) -> 0 | Q4: 700 | R4: =SUMIF($F$3:$F$42,Q4,$F$3:$F$42) -> 0 | W4: 保険 | X4: 15 | Y4: 初 | Z4: 15下 | AA4: 男 | AD4: 月データ | AE4: =HYPERLINK("#"&AD4&"!A1",AD4) -> 月データ | AG4: 時 | AH4: 保険 | AI4: 15 | AJ4: 有 | AK4: 保険 | AL4: 材料 | AM4: 電 | AN4: 15下 | AO4: 男 | AP4: 初 | AQ4: キャンペーン
A5: 3 | I5: =SUM(F5,G5,H5) -> 0 | Q5: 900 | R5: =SUMIF($F$3:$F$42,Q5,$F$3:$F$42) -> 0 | W5: =COUNTIF($D$3:$D$42,W4) -> 0 | X5: =COUNTIF($E$3:$E$42,X4) -> 0 | Y5: =COUNTIF($L$3:$L$42,AP4) -> 0 | Z5: =COUNTIF($M$3:$M$42,Z4) -> 0 | AA5: =COUNTIF($N$3:$N$42,AA4) -> 0 | AB5: 午後 | AD5: 1 | AE5: =HYPERLINK("#"&AD5&"!A1",AD5) -> 1 | AG5: 上 | AH5: 保延 | AI5: 20 | AJ5: 無 | AK5: 0 | AL5: 300 | AN5: 高 | AO5: 女 | AP5: 再 | AQ5: 深夜整体
A6: 4 | I6: =SUM(F6,G6,H6) -> 0 | Q6: 1600 | R6: =SUMIF($F$3:$F$42,Q6,$F$3:$F$42) -> 0 | W6: MT | X6: 20 | Y6: 再 | Z6: 高 | AA6: 女 | AD6: 2 | AE6: =HYPERLINK("#"&AD6&"!A1",AD6) -> 2 | AG6: 出 | AH6: MT | AI6: 30 | AK6: 600 | AL6: 500 | AN6: 大 | AP6: 2 | AQ6: 自賠¥3600
A7: 5 | I7: =SUM(F7,G7,H7) -> 0 | Q7: 1700 | R7: =SUMIF($F$3:$F$42,Q7,$F$3:$F$42) -> 0 | W7: =COUNTIF($D$3:$D$42,W6) -> 0 | X7: =COUNTIF($E$3:$E$42,X6) -> 0 | Y7: =COUNTIF($L$3:$L$42,AP5) -> 0 | Z7: =COUNTIF($M$3:$M$42,Z6) -> 0 | AA7: =COUNTIF($N$3:$N$42,AA6) -> 0 | AB7: 夕以降 | AD7: 3 | AE7: =HYPERLINK("#"&AD7&"!A1",AD7) -> 3 | AH7: MT＋I | AI7: 40 | AK7: 700 | AL7: 800 | AN7: 20代 | AP7: 3 | AQ7: 紹介割
A8: 6 | I8: =SUM(F8,G8,H8) -> 0 | Q8: 1900 | R8: =SUMIF($F$3:$F$42,Q8,$F$3:$F$42) -> 0 | W8: P・深層 | X8: 30 | Y8: 2 | Z8: 大 | AD8: 4 | AE8: =HYPERLINK("#"&AD8&"!A1",AD8) -> 4 | AH8: P・深層 | AI8: 50 | AK8: 900 | AN8: 30代 | AP8: 4 | AQ8: 商品券
A9: 7 | I9: =SUM(F9,G9,H9) -> 0 | Q9: 計 | R9: =SUM(R3:R8) -> 0 | W9: =COUNTIF($D$3:$D$42,W8) -> 0 | X9: =COUNTIF($E$3:$E$42,X8) -> 0 | Y9: =COUNTIF($L$3:$L$42,AP6) -> 0 | Z9: =COUNTIF($M$3:$M$42,Z8) -> 0 | AD9: 5 | AE9: =HYPERLINK("#"&AD9&"!A1",AD9) -> 5 | AH9: B・コン | AI9: 60 | AK9: 初診 | AN9: 40代 | AP9: 5上 | AQ9: 助成
A10: 8 | I10: =SUM(F10,G10,H10) -> 0 | W10: B・コン | X10: 40 | Y10: 3 | Z10: 20代 | AD10: 6 | AE10: =HYPERLINK("#"&AD10&"!A1",AD10) -> 6 | AH10: I・コン | AI10: 70 | AK10: 1600 | AN10: 50代 | AP10: 10上
A11: 9 | I11: =SUM(F11,G11,H11) -> 0 | Q11: 自費売上 | W11: =COUNTIF($D$3:$D$42,W10) -> 0 | X11: =COUNTIF($E$3:$E$42,X10) -> 0 | Y11: =COUNTIF($L$3:$L$42,AP7) -> 0 | Z11: =COUNTIF($M$3:$M$42,Z10) -> 0 | AD11: 7 | AE11: =HYPERLINK("#"&AD11&"!A1",AD11) -> 7 | AH11: 産後 | AI11: 80 | AK11: 1700 | AN11: 60代 | AP11: 20上
A12: 10 | I12: =SUM(F12,G12,H12) -> 0 | Q12: 1000 | R12: =SUMIF($G$3:$G$42,Q12,$G$3:$G$42) -> 0 | W12: I・コン | X12: 50 | Y12: 4 | Z12: 30代 | AD12: 8 | AE12: =HYPERLINK("#"&AD12&"!A1",AD12) -> 8 | AH12: 自賠責 | AI12: 90 | AK12: 1900 | AN12: 70代 | AP12: 週1
A13: 11 | I13: =SUM(F13,G13,H13) -> 0 | Q13: 2000 | R13: =SUMIF($G$3:$G$42,Q13,$G$3:$G$42) -> 0 | W13: =COUNTIF($D$3:$D$42,W12) -> 0 | X13: =COUNTIF($E$3:$E$42,X12) -> 0 | Y13: =COUNTIF($L$3:$L$42,AP8) -> 0 | Z13: =COUNTIF($M$3:$M$42,Z12) -> 0 | AD13: 9 | AE13: =HYPERLINK("#"&AD13&"!A1",AD13) -> 9 | AK13: 自費1 | AN13: 80代 | AP13: 週2
A14: 12 | I14: =SUM(F14,G14,H14) -> 0 | Q14: 3000 | R14: =SUMIF($G$3:$G$42,Q14,$G$3:$G$42) -> 0 | W14: 産後 | X14: 60 | Y14: 5上 | Z14: 40代 | AD14: 10 | AE14: =HYPERLINK("#"&AD14&"!A1",AD14) -> 10 | AK14: 1000 | AN14: 90代 | AP14: 週3
A15: 13 | I15: =SUM(F15,G15,H15) -> 0 | Q15: 4000 | R15: =SUMIF($G$3:$G$42,Q15,$G$3:$G$42) -> 0 | W15: =COUNTIF($D$3:$D$42,W14) -> 0 | X15: =COUNTIF($E$3:$E$42,X14) -> 0 | Y15: =COUNTIF($L$3:$L$42,AP9) -> 0 | Z15: =COUNTIF($M$3:$M$42,Z14) -> 0 | AD15: 11 | AE15: =HYPERLINK("#"&AD15&"!A1",AD15) -> 11 | AK15: 2000 | AP15: 毎
A16: 14 | I16: =SUM(F16,G16,H16) -> 0 | Q16: 5000 | R16: =SUMIF($G$3:$G$42,Q16,$G$3:$G$42) -> 0 | W16: 保延 | X16: 70 | Y16: 10上 | Z16: 50代 | AD16: 12 | AE16: =HYPERLINK("#"&AD16&"!A1",AD16) -> 12 | AK16: 3000 | AP16: 1/2W
A17: 15 | I17: =SUM(F17,G17,H17) -> 0 | Q17: 6000 | R17: =SUMIF($G$3:$G$42,Q17,$G$3:$G$42) -> 0 | W17: =COUNTIF(D3:D42,W16) -> 0 | X17: =COUNTIF($E$3:$E$42,X16) -> 0 | Y17: =COUNTIF($L$3:$L$42,AP10) -> 0 | Z17: =COUNTIF($M$3:$M$42,Z16) -> 0 | AD17: 13 | AE17: =HYPERLINK("#"&AD17&"!A1",AD17) -> 13 | AK17: 4000 | AP17: 1/3W
A18: 16 | I18: =SUM(F18,G18,H18) -> 0 | Q18: 7000 | R18: =SUMIF($G$3:$G$42,Q18,$G$3:$G$42) -> 0 | X18: 80 | Y18: 20上 | Z18: 60代 | AD18: 14 | AE18: =HYPERLINK("#"&AD18&"!A1",AD18) -> 14 | AK18: 5000 | AP18: 月1
A19: 17 | I19: =SUM(F19,G19,H19) -> 0 | Q19: 8000 | R19: =SUMIF($G$3:$G$42,Q19,$G$3:$G$42) -> 0 | X19: =COUNTIF($E$3:$E$42,X18) -> 0 | Y19: =COUNTIF($L$3:$L$42,AP11) -> 0 | Z19: =COUNTIF($M$3:$M$42,Z18) -> 0 | AD19: 15 | AE19: =HYPERLINK("#"&AD19&"!A1",AD19) -> 15 | AK19: 6000 | AP19: 不
A20: 18 | I20: =SUM(F20,G20,H20) -> 0 | Q20: 9000 | R20: =SUMIF($G$3:$G$42,Q20,$G$3:$G$42) -> 0 | X20: 90 | Y20: 毎 | Z20: 70代 | AD20: 16 | AE20: =HYPERLINK("#"&AD20&"!A1",AD20) -> 16 | AK20: 7000
A21: 19 | I21: =SUM(F21,G21,H21) -> 0 | Q21: 10000 | R21: =SUMIF($G$3:$G$42,Q21,$G$3:$G$42) -> 0 | T21: 自費売上 | X21: =COUNTIF($E$3:$E$42,X20) -> 0 | Y21: =COUNTIF($L$3:$L$42,AP15) -> 0 | Z21: =COUNTIF($M$3:$M$42,Z20) -> 0 | AD21: 17 | AE21: =HYPERLINK("#"&AD21&"!A1",AD21) -> 17 | AK21: 8000
A22: 20 | I22: =SUM(F22,G22,H22) -> 0 | Q22: 11000 | R22: =SUMIF($G$3:$G$42,Q22,$G$3:$G$42) -> 0 | T22: 2500 | U22: =SUMIF($G$3:$G$42,T22,$G$3:$G$42) -> 0 | Y22: 週1 | Z22: 80代 | AD22: 18 | AE22: =HYPERLINK("#"&AD22&"!A1",AD22) -> 18 | AK22: 9000
A23: 21 | I23: =SUM(F23,G23,H23) -> 0 | Q23: 12000 | R23: =SUMIF($G$3:$G$42,Q23,$G$3:$G$42) -> 0 | T23: 2800 | U23: =SUMIF($G$3:$G$42,T23,$G$3:$G$42) -> 0 | Y23: =COUNTIF($L$3:$L$42,AP12) -> 0 | Z23: =COUNTIF($M$3:$M$42,Z22) -> 0 | AD23: 19 | AE23: =HYPERLINK("#"&AD23&"!A1",AD23) -> 19 | AK23: 10000
A24: 22 | I24: =SUM(F24,G24,H24) -> 0 | Q24: 1700 | R24: =SUMIF($G$3:$G$42,Q24,$G$3:$G$42) -> 0 | T24: 3800 | U24: =SUMIF($G$3:$G$42,T24,$G$3:$G$42) -> 0 | Y24: 週2 | Z24: 90代 | AD24: 20 | AE24: =HYPERLINK("#"&AD24&"!A1",AD24) -> 20 | AK24: 11000
A25: 23 | I25: =SUM(F25,G25,H25) -> 0 | Q25: 2700 | R25: =SUMIF($G$3:$G$42,Q25,$G$3:$G$42) -> 0 | T25: 4500 | U25: =SUMIF($G$3:$G$42,T25,$G$3:$G$42) -> 0 | Y25: =COUNTIF($L$3:$L$42,AP13) -> 0 | Z25: =COUNTIF($M$3:$M$42,Z24) -> 0 | AD25: 21 | AE25: =HYPERLINK("#"&AD25&"!A1",AD25) -> 21 | AK25: 自費2
A26: 24 | I26: =SUM(F26,G26,H26) -> 0 | Q26: 3700 | R26: =SUMIF($G$3:$G$42,Q26,$G$3:$G$42) -> 0 | T26: 5500 | U26: =SUMIF($G$3:$G$42,T26,$G$3:$G$42) -> 0 | Y26: 週3 | AD26: 22 | AE26: =HYPERLINK("#"&AD26&"!A1",AD26) -> 22 | AK26: 1700
A27: 25 | I27: =SUM(F27,G27,H27) -> 0 | Q27: 4700 | R27: =SUMIF($G$3:$G$42,Q27,$G$3:$G$42) -> 0 | T27: 6300 | U27: =SUMIF($G$3:$G$42,T27,$G$3:$G$42) -> 0 | Y27: =COUNTIF($L$3:$L$42,AP14) -> 0 | AD27: 23 | AE27: =HYPERLINK("#"&AD27&"!A1",AD27) -> 23 | AK27: 2700
A28: 26 | I28: =SUM(F28,G28,H28) -> 0 | Q28: 5700 | R28: =SUMIF($G$3:$G$42,Q28,$G$3:$G$42) -> 0 | T28: 7800 | U28: =SUMIF($G$3:$G$42,T28,$G$3:$G$42) -> 0 | Y28: 1/2W | AD28: 24 | AE28: =HYPERLINK("#"&AD28&"!A1",AD28) -> 24 | AK28: 3700
A29: 27 | I29: =SUM(F29,G29,H29) -> 0 | Q29: 6700 | R29: =SUMIF($G$3:$G$42,Q29,$G$3:$G$42) -> 0 | T29: 28000 | U29: =SUMIF($G$3:$G$42,T29,$G$3:$G$42) -> 0 | Y29: =COUNTIF($L$3:$L$42,AP16) -> 0 | AD29: 25 | AE29: =HYPERLINK("#"&AD29&"!A1",AD29) -> 25 | AK29: 4700
A30: 28 | I30: =SUM(F30,G30,H30) -> 0 | Q30: 7700 | R30: =SUMIF($G$3:$G$42,Q30,$G$3:$G$42) -> 0 | T30: 29000 | U30: =SUMIF($G$3:$G$42,T30,$G$3:$G$42) -> 0 | Y30: 1/3W | AD30: 26 | AE30: =HYPERLINK("#"&AD30&"!A1",AD30) -> 26 | AK30: 5700
A31: 29 | I31: =SUM(F31,G31,H31) -> 0 | Q31: 8700 | R31: =SUMIF($G$3:$G$42,Q31,$G$3:$G$42) -> 0 | T31: 35000 | U31: =SUMIF($G$3:$G$42,T31,$G$3:$G$42) -> 0 | Y31: =COUNTIF($L$3:$L$42,AP17) -> 0 | AD31: 27 | AE31: =HYPERLINK("#"&AD31&"!A1",AD31) -> 27 | AK31: 6700
A32: 30 | I32: =SUM(F32,G32,H32) -> 0 | Q32: 9700 | R32: =SUMIF($G$3:$G$42,Q32,$G$3:$G$42) -> 0 | T32: 50000 | U32: =SUMIF($G$3:$G$42,T32,$G$3:$G$42) -> 0 | Y32: 月1 | AD32: 28 | AE32: =HYPERLINK("#"&AD32&"!A1",AD32) -> 28 | AK32: 7700
A33: 31 | I33: =SUM(F33,G33,H33) -> 0 | Q33: 12700 | R33: =SUMIF($G$3:$G$42,Q33,$G$3:$G$42) -> 0 | U33: =SUMIF($G$3:$G$42,T33,$G$3:$G$42) -> 0 | Y33: =COUNTIF($L$3:$L$42,AP18) -> 0 | AD33: 29 | AE33: =HYPERLINK("#"&AD33&"!A1",AD33) -> 29 | AK33: 8700
A34: 32 | I34: =SUM(F34,G34,H34) -> 0 | Q34: 計 | R34: =SUM(R12:R29) -> 0 | T34: 計 | U34: =SUM(U22:U32) -> 0 | Y34: 不 | AD34: 30 | AE34: =HYPERLINK("#"&AD34&"!A1",AD34) -> 30 | AK34: 9700
A35: 33 | I35: =SUM(F35,G35,H35) -> 0 | Y35: =COUNTIF($L$3:$L$42,AP19) -> 0 | AD35: 31 | AE35: =HYPERLINK("#"&AD35&"!A1",AD35) -> 31 | AK35: 10700
A36: 34 | I36: =SUM(F36,G36,H36) -> 0 | Q36: 材料費 | AK36: 自費3
A37: 35 | I37: =SUM(F37,G37,H37) -> 0 | Q37: 300 | R37: =SUMIF($H$3:$H$42,Q37,$H$3:$H$42) -> 0 | T37: 時田 | U37: =SUM(U38,U39) -> 0 | AK37: 2500
A38: 36 | I38: =SUM(F38,G38,H38) -> 0 | Q38: 500 | R38: =SUMIF($H$3:$H$42,Q38,$H$3:$H$42) -> 0 | T38: 保険人数 | U38: =COUNTIFS($C$3:$C$42,AG4,$F$3:$F$42,">=0") -> 0 | AK38: 3800
A39: 37 | I39: =SUM(F39,G39,H39) -> 0 | Q39: 800 | R39: =SUMIF($H$3:$H$42,Q39,$H$3:$H$42) -> 0 | T39: 自費人数 | U39: =(COUNTIFS($C:$C,AG4,$D:$D,$AH$6))+(COUNTIFS($C:$C,AG4,$D:$D,$AH$8))+(COUNTIFS($C:$C,AG4,$D:$D,AH9))+(COUNTIFS($C:$C,AG4,$D:$D,AH10)+(COUNTIFS($C:$C,AG4,$D:$D,AH11))) -> 0 | AK39: 3800
A40: 38 | I40: =SUM(F40,G40,H40) -> 0 | R40: =SUMIF($H$3:$H$42,Q40,$H$3:$H$42) -> 0 | T40: 自費売上 | U40: =SUMIF($C:$C,AG4,$G:$G) -> 0 | W40: =COUNTIFS($C$3:$C$42,AG4,G3:$G$42,">=0") -> 0 | X40: =COUNTIFS($D$3:$D$42,AH5,$G$3:$G$42,">=0") -> 0 | AK40: 5800
...

Sheet 3
A1: 日計表 | C1: 令和8年 月 3日 ()
B2: 氏名 | C2: 担 | D2: 施術 | E2: 時間 | F2: 保険 | G2: 自費 | H2: 材・販 | I2: 合計 | J2: 支払 | K2: 予約 | L2: 来院 | M2: 年齢 | N2: 性 | O2: 備考 | Q2: 保険売上
A3: 1 | I3: =SUM(F3,G3,H3) -> 0 | Q3: 600 | R3: =SUMIF($F$3:$F$42,Q3,$F$3:$F$42) -> 0 | W3: 自費 | X3: 時間 | Y3: 来院 | Z3: 年齢比 | AA3: 男女比 | AB3: 午前 | AD3: 目次 | AE3: シート | AG3: 担当 | AH3: 施術 | AI3: 時間 | AJ3: 予約 | AK3: 料金 | AL3: 延・材 | AM3: 支払 | AN3: 年齢 | AO3: 性別 | AP3: 来院 | AQ3: 備考
A4: 2 | I4: =SUM(F4,G4,H4) -> 0 | Q4: 700 | R4: =SUMIF($F$3:$F$42,Q4,$F$3:$F$42) -> 0 | W4: 保険 | X4: 15 | Y4: 初 | Z4: 15下 | AA4: 男 | AD4: 月データ | AE4: =HYPERLINK("#"&AD4&"!A1",AD4) -> 月データ | AG4: 時 | AH4: 保険 | AI4: 15 | AJ4: 有 | AK4: 保険 | AL4: 材料 | AM4: 電 | AN4: 15下 | AO4: 男 | AP4: 初 | AQ4: キャンペーン
A5: 3 | I5: =SUM(F5,G5,H5) -> 0 | Q5: 900 | R5: =SUMIF($F$3:$F$42,Q5,$F$3:$F$42) -> 0 | W5: =COUNTIF($D$3:$D$42,W4) -> 0 | X5: =COUNTIF($E$3:$E$42,X4) -> 0 | Y5: =COUNTIF($L$3:$L$42,AP4) -> 0 | Z5: =COUNTIF($M$3:$M$42,Z4) -> 0 | AA5: =COUNTIF($N$3:$N$42,AA4) -> 0 | AB5: 午後 | AD5: 1 | AE5: =HYPERLINK("#"&AD5&"!A1",AD5) -> 1 | AG5: 上 | AH5: 保延 | AI5: 20 | AJ5: 無 | AK5: 0 | AL5: 300 | AN5: 高 | AO5: 女 | AP5: 再 | AQ5: 深夜整体
